Workbook

Sheet Income statement
A1: Britannia Industries Ltd.
A2: Consolidated Profit & Loss account | B2: ------------------- in Rs. Cr. ------------------- | P2: Cost of raw materials consumed
B3: 44256 | C3: 44621 | D3: 44986 | E3: 45352 | F3: Mar 25
A4: INCOME
A5: Revenue From Operations [Gross] | B5: 12883.04 | C5: 13944.67 | D5: 15984.9 | E5: 16546.21 | F5: 17535.02
A6: Revenue From Operations [Net] | B6: 12883.04 | C6: 13944.67 | D6: 15984.9 | E6: 16546.21 | F6: 17535.02
A7: Other Operating Revenues | B7: 253.1 | C7: 191.59 | D7: 315.65 | E7: 223.06 | F7: 407.65
A8: Total Operating Revenues | B8: 13136.14 | C8: 14136.26 | D8: 16300.55 | E8: 16769.27 | F8: 17942.67
A9: Other Income | B9: 312.87 | C9: 222.83 | D9: 215.86 | E9: 214.18 | F9: 227.09
A10: Total Revenue | B10: 13449.01 | C10: 14359.09 | D10: 16516.41 | E10: 16983.45 | F10: 18169.76
A11: EXPENSES
A12: Cost Of Materials Consumed | B12: 6502.33 | C12: 7473.97 | D12: 8326.7 | E12: 8546.89 | F12: 9859.45
A13: Purchase Of Stock-In Trade | B13: 1160.89 | C13: 1361.59 | D13: 1337.13 | E13: 941.48 | F13: 809.35
A14: Changes In Inventories Of FG,WIP And Stock-In Trade | B14: -37.12 | C14: -75.26 | D14: -72.53 | E14: 3.66 | F14: -64.75
A15: Employee Benefit Expenses | B15: 527.38 | C15: 542.26 | D15: 658.38 | E15: 708.7 | F15: 704.59
A16: Finance Costs | B16: 110.9 | C16: 144.29 | D16: 169.1 | E16: 164 | F16: 138.8
A17: Depreciation And Amortisation Expenses | B17: 197.85 | C17: 200.54 | D17: 225.91 | E17: 300.46 | F17: 313.34
A18: Other Expenses | B18: 2473.37 | C18: 2632.19 | D18: 3219.96 | E18: 3398.7 | F18: 3446.88
A19: Total Expenses | B19: 10935.6 | C19: 12279.58 | D19: 13864.65 | E19: 14063.89 | F19: 15207.66
A20: Profit/Loss Before Exceptional, ExtraOrdinary Items And Tax | B20: 2513.41 | C20: 2079.51 | D20: 2651.76 | E20: 2919.56 | F20: 2962.1
A21: Exceptional Items | B21: -0.61 | C21: -0.98 | D21: 375.6 | E21: -2.9 | F21: -24.79
A22: Profit/Loss Before Tax | B22: 2512.8 | C22: 2078.53 | D22: 3027.36 | E22: 2916.66 | F22: 2937.31
A23: Tax Expenses-Continued Operations
A24: Current Tax | B24: 657.12 | C24: 612.24 | D24: 720.97 | E24: 765.69 | F24: 741.68
A25: Deferred Tax | B25: 5.9 | C25: -49.89 | D25: -4.52 | E25: 13.56 | F25: 7.03
A26: Total Tax Expenses | B26: 663.02 | C26: 562.35 | D26: 716.45 | E26: 779.25 | F26: 748.71
A27: Profit/Loss After Tax And Before ExtraOrdinary Items | B27: 1849.78 | C27: 1516.18 | D27: 2310.91 | E27: 2137.41 | F27: 2188.6
A28: Profit/Loss From Continuing Operations | B28: 1849.78 | C28: 1516.18 | D28: 2310.91 | E28: 2137.41 | F28: 2188.6
A29: Profit/Loss For The Period | B29: 1849.78 | C29: 1516.18 | D29: 2310.91 | E29: 2137.41 | F29: 2188.6
A30: Minority Interest | B30: 13.31 | C30: 8.84 | D30: 5.45 | E30: 5.59 | F30: 0.87
A31: Share Of Profit/Loss Of Associates | B31: 0.81 | C31: -0.2 | D31: 5.41 | E31: -3.19 | F31: -10.74
A32: Consolidated Profit/Loss After MI And Associates | B32: 1863.9 | C32: 1524.82 | D32: 2321.77 | E32: 2139.81 | F32: 2178.73
A33: OTHER ADDITIONAL INFORMATION
A34: EARNINGS PER SHARE
A35: Basic EPS (Rs.) | B35: 77 | C35: 63 | D35: 96 | E35: 89 | F35: 90
A36: Diluted EPS (Rs.) | B36: 77 | C36: 63 | D36: 96 | E36: 89 | F36: 90
A37: DIVIDEND AND DIVIDEND PERCENTAGE
A38: Equity Share Dividend | B38: 2839.66 | C38: 1794.47 | D38: 1360.91 | E38: 1734.25 | F38: 1770.38

Sheet DASHBOARD
A1: Britannia Industries Ltd. Dashboard
A4: Average Revenue Growth | D4: Average EBITDA Growth | G4: Average PAT Growth | J4: Average EBITDAM Growth
A5: =AVERAGE('WORKIN SHEET'!B5:B9) -> 0.081991278 | D5: =AVERAGE('WORKIN SHEET'!C5:C9) -> 0.058850073 | G5: =AVERAGE('WORKIN SHEET'!D6:D9) -> 0.058899514 | J5: =AVERAGE('WORKIN SHEET'!F5:F9) -> 0.19306688
A8: Average PATM Growth | D8: Average CFO | G8: Average CFI | J8: Average ICR
A9: =AVERAGE('YOY GROWTH'!J18:N18) -> 0.12358102 | D9: =AVERAGE('one pager'!C39:G39) -> 2151.2 | G9: =AVERAGE('one pager'!C40:G40) -> 82.4 | J9: =AVERAGE('one pager'!C17:G17) -> 19.38007

Sheet BALANCE C
A1: Britannia Industries Ltd. Balance Sheet
A5: Particulars | B5: 44256 | C5: 44621 | D5: 44986 | E5: 45352 | F5: Mar 25
A7: EQUITIES AND LIABILITIES
A8: SHAREHOLDER'S FUNDS
A9: Equity Share Capital | B9: 24.09 | C9: 24.09 | D9: 24.09 | E9: 24.09 | F9: 24.09
A10: Total Share Capital | B10: 24.09 | C10: 24.09 | D10: 24.09 | E10: 24.09 | F10: 24.09
A11: Reserves and Surplus | B11: 3495.47 | C11: 2534.01 | D11: 3510.18 | E11: 3917.43 | F11: 4331.63
A12: Total Reserves and Surplus | B12: 3495.47 | C12: 2534.01 | D12: 3510.18 | E12: 3917.43 | F12: 4331.63
A13: Employees Stock Options | B13: 28.1 | C13: 0 | D13: 0 | E13: 0 | F13: 0
A14: Total Shareholders Funds | B14: 3547.66 | C14: 2558.1 | D14: 3534.27 | E14: 3941.52 | F14: 4355.72
A15: Minority Interest | B15: 36.34 | C15: 27.5 | D15: 30.23 | E15: 24.5 | F15: 25.6
A16: NON-CURRENT LIABILITIES
A17: Long Term Borrowings | B17: 747.75 | C17: 706.99 | D17: 1551.8 | E17: 904.72 | F17: 712.94
A18: Deferred Tax Liabilities [Net] | B18: 8.69 | C18: 0.81 | D18: 1.87 | E18: 2.06 | F18: 1.8
A19: Other Long Term Liabilities | B19: 54.07 | C19: 66.4 | D19: 74.51 | E19: 85.79 | F19: 91.66
A20: Long Term Provisions | B20: 0 | C20: 0 | D20: 25.64 | E20: 30.56 | F20: 32.57
A21: Total Non-Current Liabilities | B21: 810.51 | C21: 774.2 | D21: 1653.82 | E21: 1023.13 | F21: 838.97
A22: CURRENT LIABILITIES
A23: Short Term Borrowings | B23: 1339.42 | C23: 1758.55 | D23: 1428.71 | E23: 1136.49 | F23: 511.83
A24: Trade Payables | B24: 1314.75 | C24: 1285.22 | D24: 1448.81 | E24: 1627.48 | F24: 1752.23
A25: Other Current Liabilities | B25: 572.63 | C25: 626.85 | D25: 743.49 | E25: 761.24 | F25: 749.54
A26: Short Term Provisions | B26: 387.47 | C26: 485.11 | D26: 513.39 | E26: 559.2 | F26: 604.66
A27: Total Current Liabilities | B27: 3614.27 | C27: 4155.73 | D27: 4134.4 | E27: 4084.41 | F27: 3618.26
A28: Total Capital And Liabilities | B28: 8008.78 | C28: 7515.53 | D28: 9352.72 | E28: 9073.56 | F28: 8838.55
A29: ASSETS
A30: NON-CURRENT ASSETS
A31: Tangible Assets | B31: 1648.51 | C31: 1598 | D31: 2512.82 | E31: 2630.42 | F31: 2763.51
A32: Intangible Assets | B32: 8.54 | C32: 15.6 | D32: 14.24 | E32: 10.9 | F32: 7.51
A33: Capital Work-In-Progress | B33: 116.52 | C33: 535.68 | D33: 105 | E33: 187.54 | F33: 89.2
A34: Fixed Assets | B34: 1773.57 | C34: 2149.28 | D34: 2632.06 | E34: 2828.86 | F34: 2860.22
A35: Non-Current Investments | B35: 1387.44 | C35: 928.64 | D35: 1523.25 | E35: 1070.21 | F35: 1753.79
A36: Deferred Tax Assets [Net] | B36: 9.66 | C36: 44.93 | D36: 43.64 | E36: 43.88 | F36: 36.59
A37: Long Term Loans And Advances | B37: 74.58 | C37: 100 | D37: 150 | E37: 0 | F37: 0
A38: Other Non-Current Assets | B38: 207.95 | C38: 182.65 | D38: 129.38 | E38: 152.13 | F38: 141.49
A39: Total Non-Current Assets | B39: 3589.1 | C39: 3545.11 | D39: 4606.49 | E39: 4224.9 | F39: 4924.87
A40: CURRENT ASSETS
A41: Current Investments | B41: 1393.25 | C41: 833.73 | D41: 1800.99 | E41: 1696.51 | F41: 1111.64
A42: Inventories | B42: 1091.49 | C42: 1367.49 | D42: 1193.26 | E42: 1181.22 | F42: 1236.51
A43: Trade Receivables | B43: 257.27 | C43: 331.93 | D43: 328.94 | E43: 393.33 | F43: 448.61
A44: Cash And Cash Equivalents | B44: 211.34 | C44: 184.9 | D44: 197.98 | E44: 446.35 | F44: 312.48
...

Sheet Sheet8
A2: Cash Flow of Britannia Industries (in Rs. Cr.) | B2: 45717 | C2: 45352 | D2: 44986 | E2: 44621 | F2: 44256
A3: Net Profit/Loss Before Extraordinary Items And Tax | B3: 2937.31 | C3: 2916.66 | D3: 3027.36 | E3: 2078.53 | F3: 2512.8
A4: Net CashFlow From Operating Activities | B4: 2480.65 | C4: 2572.98 | D4: 2526.21 | E4: 1299.52 | F4: 1851.07
A5: Net Cash Used In Investing Activities | B5: 84.36 | C5: 475.5 | D5: -1517.06 | E5: 910.89 | F5: 461.26
A6: Net Cash Used From Financing Activities | B6: -2761.86 | C6: -2830.48 | D6: -1028.37 | E6: -2245.84 | F6: -2243.69
A7: Foreign Exchange Gains / Losses | B7: 2.64 | C7: 1.29 | D7: 10.06 | E7: 3.3 | F7: -2.44
A8: Adjustments On Amalgamation Merger Demerger Others | B8: 0 | C8: 0 | D8: 0 | E8: 0 | F8: 0
A9: Net Inc/Dec In Cash And Cash Equivalents | B9: -194.21 | C9: 219.29 | D9: -9.16 | E9: -32.13 | F9: 66.2
A10: Cash And Cash Equivalents Begin of Year | B10: 319.45 | C10: 100.16 | D10: 109.32 | E10: 141.45 | F10: 75.25
A11: Cash And Cash Equivalents End Of Year | B11: 125.24 | C11: 319.45 | D11: 100.16 | E11: 109.32 | F11: 141.45

Sheet YOY GROWTH
A2: Analyst
B3: 44256 | C3: 44621 | D3: 44986 | E3: 45352 | F3: Mar 25
A4: Revenue from operations | B4: ='Income statement'!B8 -> 13136.14 | C4: ='Income statement'!C8 -> 14136.26 | D4: ='Income statement'!D8 -> 16300.55 | E4: ='Income statement'!E8 -> 16769.27 | F4: ='Income statement'!F8 -> 17942.67
A5: Other Income | B5: ='Income statement'!B9 -> 312.87 | C5: ='Income statement'!C9 -> 222.83 | D5: ='Income statement'!D9 -> 215.86 | E5: ='Income statement'!E9 -> 214.18 | F5: ='Income statement'!F9 -> 227.09
A6: Total Income | B6: =B4+B5 -> 13449.01 | C6: =C4+C5 -> 14359.09 | D6: =D4+D5 -> 16516.41 | E6: =E4+E5 -> 16983.45 | F6: =F4+F5 -> 18169.76
A7: Cost Of Goods Sold | B7: ='Income statement'!B12+'Income statement'!B13+'Income statement'!B14 -> 7626.1 | C7: ='Income statement'!C12+'Income statement'!C13+'Income statement'!C14 -> 8760.3 | D7: ='Income statement'!D12+'Income statement'!D13+'Income statement'!D14 -> 9591.3 | E7: ='Income statement'!E12+'Income statement'!E13+'Income statement'!E14 -> 9492.03 | F7: ='Income statement'!F12+'Income statement'!F13+'Income statement'!F14 -> 10604.05
A8: Gross Profit | B8: =B6-B7 -> 5822.91 | C8: =C6-C7 -> 5598.79 | D8: =D6-D7 -> 6925.11 | E8: =E6-E7 -> 7491.42 | F8: =F6-F7 -> 7565.71
A9: SGA | B9: ='Income statement'!B15+'Income statement'!B18 -> 3000.75 | C9: ='Income statement'!C15+'Income statement'!C18 -> 3174.45 | D9: ='Income statement'!D15+'Income statement'!D18 -> 3878.34 | E9: ='Income statement'!E15+'Income statement'!E18 -> 4107.4 | F9: ='Income statement'!F15+'Income statement'!F18 -> 4151.47 | I9: Analysis
A10: EBITDA | B10: =B8-B9 -> 2822.16 | C10: =C8-C9 -> 2424.34 | D10: =D8-D9 -> 3046.77 | E10: =E8-E9 -> 3384.02 | F10: =F8-F9 -> 3414.24 | I10: Particular | J10: 44256 | K10: 44621 | L10: 44986 | M10: 45352 | N10: Mar 25
A11: Depreciation and amortisation | B11: ='Income statement'!B17 -> 197.85 | C11: ='Income statement'!C17 -> 200.54 | D11: ='Income statement'!D17 -> 225.91 | E11: ='Income statement'!E17 -> 300.46 | F11: ='Income statement'!F17 -> 313.34 | I11: Revenue YOY Growth | K11: =('YOY GROWTH'!C4-'YOY GROWTH'!B4)/'YOY GROWTH'!B4 -> 0.076134999 | L11: =('YOY GROWTH'!D4-'YOY GROWTH'!C4)/'YOY GROWTH'!C4 -> 0.15310202 | M11: =('YOY GROWTH'!E4-'YOY GROWTH'!D4)/'YOY GROWTH'!D4 -> 0.028754858 | N11: =('YOY GROWTH'!F4-'YOY GROWTH'!E4)/'YOY GROWTH'!E4 -> 0.069973231
A12: EBIT | B12: =B10-B11 -> 2624.31 | C12: =C10-C11 -> 2223.8 | D12: =D10-D11 -> 2820.86 | E12: =E10-E11 -> 3083.56 | F12: =F10-F11 -> 3100.9 | I12: EBITDA YOY Growth | K12: =('YOY GROWTH'!C10-'YOY GROWTH'!B10)/'YOY GROWTH'!B10 -> -0.14096295 | L12: =('YOY GROWTH'!D10-'YOY GROWTH'!C10)/'YOY GROWTH'!C10 -> 0.25674204 | M12: =('YOY GROWTH'!E10-'YOY GROWTH'!D10)/'YOY GROWTH'!D10 -> 0.11069099 | N12: =('YOY GROWTH'!F10-'YOY GROWTH'!E10)/'YOY GROWTH'!E10 -> 0.0089302073
A13: Interest | B13: ='Income statement'!B16 -> 110.9 | C13: ='Income statement'!C16 -> 144.29 | D13: ='Income statement'!D16 -> 169.1 | E13: ='Income statement'!E16 -> 164 | F13: ='Income statement'!F16 -> 138.8 | I13: PAT YOY Growth | K13: =('YOY GROWTH'!C16-'YOY GROWTH'!B16)/'YOY GROWTH'!B16 -> -0.18008636 | L13: =('YOY GROWTH'!D16-'YOY GROWTH'!C16)/'YOY GROWTH'!C16 -> 0.27561365 | M13: =('YOY GROWTH'!E16-'YOY GROWTH'!D16)/'YOY GROWTH'!D16 -> 0.10592618 | N13: =('YOY GROWTH'!F16-'YOY GROWTH'!E16)/'YOY GROWTH'!E16 -> 0.034144587
A14: EBT | B14: =B12-B13 -> 2513.41 | C14: =C12-C13 -> 2079.51 | D14: =D12-D13 -> 2651.76 | E14: =E12-E13 -> 2919.56 | F14: =F12-F13 -> 2962.1 | I14: Gross Profit Margin | K14: ='YOY GROWTH'!B8/'YOY GROWTH'!B4 -> 0.44327405 | L14: ='YOY GROWTH'!C8/'YOY GROWTH'!C4 -> 0.39605879 | M14: ='YOY GROWTH'!D8/'YOY GROWTH'!D4 -> 0.42483904 | N14: ='YOY GROWTH'!E8/'YOY GROWTH'!E4 -> 0.44673501
A15: Tax | B15: ='Income statement'!B24+'Income statement'!B25 -> 663.02 | C15: ='Income statement'!C24+'Income statement'!C25 -> 562.35 | D15: ='Income statement'!D24+'Income statement'!D25 -> 716.45 | E15: ='Income statement'!E24+'Income statement'!E25 -> 779.25 | F15: ='Income statement'!F24+'Income statement'!F25 -> 748.71 | I15: EBITDAM YOY Growth | J15: ='YOY GROWTH'!B10/'YOY GROWTH'!B4 -> 0.21483937 | K15: ='YOY GROWTH'!C10/'YOY GROWTH'!C4 -> 0.17149798 | L15: ='YOY GROWTH'!D10/'YOY GROWTH'!D4 -> 0.1869121 | M15: ='YOY GROWTH'!E10/'YOY GROWTH'!E4 -> 0.20179889 | N15: ='YOY GROWTH'!F10/'YOY GROWTH'!F4 -> 0.19028606
A16: Profit after Tax | B16: =B14-B15 -> 1850.39 | C16: =C14-C15 -> 1517.16 | D16: =D14-D15 -> 1935.31 | E16: =E14-E15 -> 2140.31 | F16: =F14-F15 -> 2213.39 | I16: NPM | J16: ='YOY GROWTH'!B18/'YOY GROWTH'!B4 -> 0.14193743 | K16: ='YOY GROWTH'!C18/'YOY GROWTH'!C4 -> 0.1079352 | L16: ='YOY GROWTH'!D18/'YOY GROWTH'!D4 -> 0.1193929 | M16: ='YOY GROWTH'!E18/'YOY GROWTH'!E4 -> 0.12777599 | N16: ='YOY GROWTH'!F18/'YOY GROWTH'!F4 -> 0.12280892
A17: Share of Associates | B17: ='Income statement'!B30+'Income statement'!B31 -> 14.12 | C17: ='Income statement'!C30+'Income statement'!C31 -> 8.64 | D17: ='Income statement'!D30+'Income statement'!D31 -> 10.86 | E17: ='Income statement'!E30+'Income statement'!E31 -> 2.4 | F17: ='Income statement'!F30+'Income statement'!F31 -> -9.87 | I17: Interest Coverage Ratio | J17: ='YOY GROWTH'!B12/'YOY GROWTH'!B13 -> 23.663751 | K17: ='YOY GROWTH'!C12/'YOY GROWTH'!C13 -> 15.412017 | L17: ='YOY GROWTH'!D12/'YOY GROWTH'!D13 -> 16.681609 | M17: ='YOY GROWTH'!E12/'YOY GROWTH'!E13 -> 18.802195 | N17: ='YOY GROWTH'!F12/'YOY GROWTH'!F13 -> 22.340778
A18: Profit before Extraordinary items | B18: =B16+B17 -> 1864.51 | C18: =C16+C17 -> 1525.8 | D18: =D16+D17 -> 1946.17 | E18: =E16+E17 -> 2142.71 | F18: =F16+F17 -> 2203.52 | I18: PATM YOY Growth | J18: =B16/B4 -> 0.14086254 | K18: =C16/C4 -> 0.107324 | L18: =D16/D4 -> 0.11872667 | M18: =E16/E4 -> 0.12763287 | N18: =F16/F4 -> 0.12335901
A19: Extraordinary item | B19: ='Income statement'!B21 -> -0.61 | C19: ='Income statement'!C21 -> -0.98 | D19: ='Income statement'!D21 -> 375.6 | E19: ='Income statement'!E21 -> -2.9 | F19: ='Income statement'!F21 -> -24.79 | I19: RESERVES YOY GROWTH
A20: Profit after extraordinary items | B20: =B18+B19 -> 1863.9 | C20: =C18+C19 -> 1524.82 | D20: =D18+D19 -> 2321.77 | E20: =E18+E19 -> 2139.81 | F20: =F18+F19 -> 2178.73

Sheet RATIOS
A1: Ratios
A2: Particulars | B2: 44256 | C2: 44621 | D2: 44986 | E2: 45352 | F2: Mar 25
A3: Reserves to NCL | B3: ='Balance Sheet'!B9/'Balance Sheet'!B18 -> 5.1630332 | C3: ='Balance Sheet'!C9/'Balance Sheet'!C18 -> 3.8288683 | D3: ='Balance Sheet'!D9/'Balance Sheet'!D18 -> 2.122468 | E3: ='Balance Sheet'!E9/'Balance Sheet'!E18 -> 3.273069 | F3: ='Balance Sheet'!F9/'Balance Sheet'!F18 -> 4.3126797
A4: Debt to Equity | B4: ='Balance Sheet'!B14/'Balance Sheet'!B6 -> 29.594853 | C4: ='Balance Sheet'!C14/'Balance Sheet'!C6 -> 37.555832 | D4: ='Balance Sheet'!D14/'Balance Sheet'!D6 -> 64.41677 | E4: ='Balance Sheet'!E14/'Balance Sheet'!E6 -> 29.347862 | F4: ='Balance Sheet'!F14/'Balance Sheet'!F6 -> 31.039851
A5: Current Ratio | B5: ='Balance Sheet'!B44/'Balance Sheet'!B24 -> 1.081647 | C5: ='Balance Sheet'!C44/'Balance Sheet'!C24 -> 1.1871139 | D5: ='Balance Sheet'!D44/'Balance Sheet'!D24 -> 1.1479852 | E5: ='Balance Sheet'!E44/'Balance Sheet'!E24 -> 0.95540856 | F5: ='Balance Sheet'!F44/'Balance Sheet'!F24 -> 1.2228417
A6: Quick Ratio | B6: =('Balance Sheet'!B44-'Balance Sheet'!B39)/'Balance Sheet'!B24 -> 0.73990537 | C6: =('Balance Sheet'!C44-'Balance Sheet'!C39)/'Balance Sheet'!C24 -> 0.89791182 | D6: =('Balance Sheet'!D44-'Balance Sheet'!D39)/'Balance Sheet'!D24 -> 0.85936774 | E6: =('Balance Sheet'!E44-'Balance Sheet'!E39)/'Balance Sheet'!E24 -> 0.62634724 | F6: =('Balance Sheet'!F44-'Balance Sheet'!F39)/'Balance Sheet'!F24 -> 0.92084709
A7: Days Receivables | B7: =('Balance Sheet'!B40/'Income statement'!B6)*365 -> 12.709939 | C7: =('Balance Sheet'!C40/'Income statement'!C6)*365 -> 10.295364 | D7: =('Balance Sheet'!D40/'Income statement'!D6)*365 -> 7.5110323 | E7: =('Balance Sheet'!E40/'Income statement'!E6)*365 -> 7.3221874 | F7: =('Balance Sheet'!F40/'Income statement'!F6)*365 -> 5.3552006
A8: Days Payables | B8: =('Balance Sheet'!B21/'YOY GROWTH'!B7)*365 -> 83.865141 | C8: =('Balance Sheet'!C21/'YOY GROWTH'!C7)*365 -> 67.809344 | D8: =('Balance Sheet'!D21/'YOY GROWTH'!D7)*365 -> 55.13493 | E8: =('Balance Sheet'!E21/'YOY GROWTH'!E7)*365 -> 49.420967 | F8: =('Balance Sheet'!F21/'YOY GROWTH'!F7)*365 -> 45.254761
A9: Inventory Turnover Ratio | B9: =('YOY GROWTH'!B4/'Balance Sheet'!B39) -> 10.623561 | C9: =('YOY GROWTH'!C4/'Balance Sheet'!C39) -> 11.967508 | D9: =('YOY GROWTH'!D4/'Balance Sheet'!D39) -> 13.660518 | E9: =('YOY GROWTH'!E4/'Balance Sheet'!E39) -> 12.26281 | F9: =('YOY GROWTH'!F4/'Balance Sheet'!F39) -> 16.438694
A10: Debtor Turnover Ratio | B10: ='YOY GROWTH'!B4/'Balance Sheet'!B40 -> 29.281871 | C10: ='YOY GROWTH'!C4/'Balance Sheet'!C40 -> 35.939949 | D10: ='YOY GROWTH'!D4/'Balance Sheet'!D40 -> 49.554782 | E10: ='YOY GROWTH'!E4/'Balance Sheet'!E40 -> 50.520501 | F10: ='YOY GROWTH'!F4/'Balance Sheet'!F40 -> 69.742566
A11: Creditor Turnover Ratio | B11: ='YOY GROWTH'!B7/'Balance Sheet'!B21 -> 4.3522254 | C11: ='YOY GROWTH'!C7/'Balance Sheet'!C21 -> 5.382739 | D11: ='YOY GROWTH'!D7/'Balance Sheet'!D21 -> 6.6201227 | E11: ='YOY GROWTH'!E7/'Balance Sheet'!E21 -> 7.3855293 | F11: ='YOY GROWTH'!F7/'Balance Sheet'!F21 -> 8.0654497

Sheet Balance Sheet
A1: Britannia Industries
B2: ------------------- in Rs. Cr. -------------------
B3: Mar 25 | C3: 45352 | D3: 44986 | E3: 44621 | F3: 44256
A4: EQUITIES AND LIABILITIES
A5: SHAREHOLDER'S FUNDS
A6: Equity Share Capital | B6: 24.09 | C6: 24.09 | D6: 24.09 | E6: 24.09 | F6: 24.09
A7: Total Share Capital | B7: 24.09 | C7: 24.09 | D7: 24.09 | E7: 24.09 | F7: 24.09
A8: Reserves and Surplus | B8: 4331.63 | C8: 3917.43 | D8: 3510.18 | E8: 2534.01 | F8: 3495.47
A9: Total Reserves and Surplus | B9: 4331.63 | C9: 3917.43 | D9: 3510.18 | E9: 2534.01 | F9: 3495.47
A10: Employees Stock Options | B10: 0 | C10: 0 | D10: 0 | E10: 0 | F10: 28.1
A11: Total Shareholders Funds | B11: 4355.72 | C11: 3941.52 | D11: 3534.27 | E11: 2558.1 | F11: 3547.66
A12: Minority Interest | B12: 25.6 | C12: 24.5 | D12: 30.23 | E12: 27.5 | F12: 36.34
A13: NON-CURRENT LIABILITIES
A14: Long Term Borrowings | B14: 712.94 | C14: 904.72 | D14: 1551.8 | E14: 706.99 | F14: 747.75
A15: Deferred Tax Liabilities [Net] | B15: 1.8 | C15: 2.06 | D15: 1.87 | E15: 0.81 | F15: 8.69
A16: Other Long Term Liabilities | B16: 91.66 | C16: 85.79 | D16: 74.51 | E16: 66.4 | F16: 54.07
A17: Long Term Provisions | B17: 32.57 | C17: 30.56 | D17: 25.64 | E17: 0 | F17: 0
A18: Total Non-Current Liabilities | B18: 838.97 | C18: 1023.13 | D18: 1653.82 | E18: 774.2 | F18: 810.51
A19: CURRENT LIABILITIES
A20: Short Term Borrowings | B20: 511.83 | C20: 1136.49 | D20: 1428.71 | E20: 1758.55 | F20: 1339.42
A21: Trade Payables | B21: 1752.23 | C21: 1627.48 | D21: 1448.81 | E21: 1285.22 | F21: 1314.75
A22: Other Current Liabilities | B22: 749.54 | C22: 761.24 | D22: 743.49 | E22: 626.85 | F22: 572.63
A23: Short Term Provisions | B23: 604.66 | C23: 559.2 | D23: 513.39 | E23: 485.11 | F23: 387.47
A24: Total Current Liabilities | B24: 3618.26 | C24: 4084.41 | D24: 4134.4 | E24: 4155.73 | F24: 3614.27
A25: Total Capital And Liabilities | B25: 8838.55 | C25: 9073.56 | D25: 9352.72 | E25: 7515.53 | F25: 8008.78
A26: ASSETS
A27: NON-CURRENT ASSETS
A28: Tangible Assets | B28: 2763.51 | C28: 2630.42 | D28: 2512.82 | E28: 1598 | F28: 1648.51
A29: Intangible Assets | B29: 7.51 | C29: 10.9 | D29: 14.24 | E29: 15.6 | F29: 8.54
A30: Capital Work-In-Progress | B30: 89.2 | C30: 187.54 | D30: 105 | E30: 535.68 | F30: 116.52
A31: Fixed Assets | B31: 2860.22 | C31: 2828.86 | D31: 2632.06 | E31: 2149.28 | F31: 1773.57
A32: Non-Current Investments | B32: 1753.79 | C32: 1070.21 | D32: 1523.25 | E32: 928.64 | F32: 1387.44
A33: Deferred Tax Assets [Net] | B33: 36.59 | C33: 43.88 | D33: 43.64 | E33: 44.93 | F33: 9.66
A34: Long Term Loans And Advances | B34: 0 | C34: 0 | D34: 150 | E34: 100 | F34: 74.58
A35: Other Non-Current Assets | B35: 141.49 | C35: 152.13 | D35: 129.38 | E35: 182.65 | F35: 207.95
A36: Total Non-Current Assets | B36: 4924.87 | C36: 4224.9 | D36: 4606.49 | E36: 3545.11 | F36: 3589.1
A37: CURRENT ASSETS
A38: Current Investments | B38: 1111.64 | C38: 1696.51 | D38: 1800.99 | E38: 833.73 | F38: 1393.25
A39: Inventories | B39: 1236.51 | C39: 1181.22 | D39: 1193.26 | E39: 1367.49 | F39: 1091.49
A40: Trade Receivables | B40: 448.61 | C40: 393.33 | D40: 328.94 | E40: 331.93 | F40: 257.27
...

Sheet CFS
A1: Cash Flow Statement of Britannia Industries Ltd.
A2: Particulars | B2: 44256 | C2: 44621 | D2: 44986 | E2: 45352 | F2: 45717
A3: Cash from Operating Activity | B3: 1876 | C3: 1300 | D3: 2526 | E3: 2573 | F3: 2481
A4: Cash from Investing Activity | B4: 433 | C4: 914 | D4: -1507 | E4: 485 | F4: 87
A5: Cash from Financing Activity | B5: -2242 | C5: -2246 | D5: -1028 | E5: -2839 | F5: -2762
A6: Net Cash Flow | B6: 66 | C6: -32 | D6: -9 | E6: 219 | F6: -194

Sheet one pager (2)
B1: BRITANNIA INDUSTRIES LTD.
B9: Analysis | J9: Average NPM Growth | M9: Average EBITDAM Growth | P9: Year | Q9: Revenue Yoy Growth | R9: EBITDA Yoy Growth | S9: PAT yoy Growth | T9: Gross Profit Margin | U9: EBITDAM YOY Growth | V9: NPM | W9: Interest Coverage Ratio | X9: Reserves to NCL | Y9: Debt to Equity | Z9: Current Ratio | AA9: Quick Ratio | AB9: Days Receivables | AC9: Days Payables | AD9: Inventory Turnover Ratio | AE9: Debtor Turnover Ratio | AF9: Creditor Turnover Ratio | AG9: CFO YOY Growth | AH9: CFI YOY Growth | AI9: CFF YOY Growth | AJ9: Net Cash Flow Growth | AK9: Average CFO | AL9: Average CFI | AM9: Average CFF
B10: Particular | C10: 44256 | D10: 44621 | E10: 44986 | F10: 45352 | G10: 45717 | H10: Trend | J10: =AVERAGE(C16:G16) -> 0.12397009 | M10: =AVERAGE(C15:G15) -> 0.19306688 | P10: 44256 | U10: 0.21483937 | V10: 0.14193743 | W10: 23.663751 | X10: 5.1630332 | Y10: 29.594853 | Z10: 1.081647 | AA10: 0.73990537 | AB10: 12.709939 | AC10: 83.865141 | AD10: 10.623561 | AE10: 29.281871 | AF10: 4.3522254
B11: Revenue Yoy Growth | D11: =('YOY GROWTH'!C4-'YOY GROWTH'!B4)/'YOY GROWTH'!B4 -> 0.076134999 | E11: =('YOY GROWTH'!D4-'YOY GROWTH'!C4)/'YOY GROWTH'!C4 -> 0.15310202 | F11: =('YOY GROWTH'!E4-'YOY GROWTH'!D4)/'YOY GROWTH'!D4 -> 0.028754858 | G11: =('YOY GROWTH'!F4-'YOY GROWTH'!E4)/'YOY GROWTH'!E4 -> 0.069973231 | P11: 44621 | Q11: 0.076134999 | R11: -0.14096295 | S11: -0.18008636 | T11: 0.44327405 | U11: 0.17149798 | V11: 0.1079352 | W11: 15.412017 | X11: 3.8288683 | Y11: 37.555832 | Z11: 1.1871139 | AA11: 0.89791182 | AB11: 10.295364 | AC11: 67.809344 | AD11: 11.967508 | AE11: 35.939949 | AF11: 5.382739 | AG11: -0.30703625 | AH11: 1.1108545 | AI11: 0.0017841213 | AJ11: -1.4848485
B12: EBITDA Yoy Growth | D12: =('YOY GROWTH'!C10-'YOY GROWTH'!B10)/'YOY GROWTH'!B10 -> -0.14096295 | E12: =('YOY GROWTH'!D10-'YOY GROWTH'!C10)/'YOY GROWTH'!C10 -> 0.25674204 | F12: =('YOY GROWTH'!E10-'YOY GROWTH'!D10)/'YOY GROWTH'!D10 -> 0.11069099 | G12: =('YOY GROWTH'!F10-'YOY GROWTH'!E10)/'YOY GROWTH'!E10 -> 0.0089302073 | P12: 44986 | Q12: 0.15310202 | R12: 0.25674204 | S12: 0.27561365 | T12: 0.39605879 | U12: 0.1869121 | V12: 0.1193929 | W12: 16.681609 | X12: 2.122468 | Y12: 64.41677 | Z12: 1.1479852 | AA12: 0.85936774 | AB12: 7.5110323 | AC12: 55.13493 | AD12: 13.660518 | AE12: 49.554782 | AF12: 6.6201227 | AG12: 0.94307692 | AH12: -2.6487965 | AI12: -0.54229742 | AJ12: -0.71875
B13: PAT yoy Growth | D13: =('YOY GROWTH'!C16-'YOY GROWTH'!B16)/'YOY GROWTH'!B16 -> -0.18008636 | E13: =('YOY GROWTH'!D16-'YOY GROWTH'!C16)/'YOY GROWTH'!C16 -> 0.27561365 | F13: =('YOY GROWTH'!E16-'YOY GROWTH'!D16)/'YOY GROWTH'!D16 -> 0.10592618 | G13: =('YOY GROWTH'!F16-'YOY GROWTH'!E16)/'YOY GROWTH'!E16 -> 0.034144587 | P13: 45352 | Q13: 0.028754858 | R13: 0.11069099 | S13: 0.10592618 | T13: 0.42483904 | U13: 0.20179889 | V13: 0.12777599 | W13: 18.802195 | X13: 3.273069 | Y13: 29.347862 | Z13: 0.95540856 | AA13: 0.62634724 | AB13: 7.3221874 | AC13: 49.420967 | AD13: 12.26281 | AE13: 50.520501 | AF13: 7.3855293 | AG13: 0.018606492 | AH13: -1.3218315 | AI13: 1.7616732 | AJ13: -25.333333
B14: Gross Profit Margin | D14: ='YOY GROWTH'!B8/'YOY GROWTH'!B4 -> 0.44327405 | E14: ='YOY GROWTH'!C8/'YOY GROWTH'!C4 -> 0.39605879 | F14: ='YOY GROWTH'!D8/'YOY GROWTH'!D4 -> 0.42483904 | G14: ='YOY GROWTH'!E8/'YOY GROWTH'!E4 -> 0.44673501 | P14: 45717 | Q14: 0.069973231 | R14: 0.0089302073 | S14: 0.034144587 | T14: 0.44673501 | U14: 0.19028606 | V14: 0.12280892 | W14: 22.340778 | X14: 4.3126797 | Y14: 31.039851 | Z14: 1.2228417 | AA14: 0.92084709 | AB14: 5.3552006 | AC14: 45.254761 | AD14: 16.438694 | AE14: 69.742566 | AF14: 8.0654497 | AG14: -0.035755927 | AH14: -0.82061856 | AI14: -0.027122226 | AJ14: -1.8858447 | AK14: 2151.2 | AL14: 82.4 | AM14: -2223.4
B15: EBITDAM YOY Growth | C15: ='YOY GROWTH'!B10/'YOY GROWTH'!B4 -> 0.21483937 | D15: ='YOY GROWTH'!C10/'YOY GROWTH'!C4 -> 0.17149798 | E15: ='YOY GROWTH'!D10/'YOY GROWTH'!D4 -> 0.1869121 | F15: ='YOY GROWTH'!E10/'YOY GROWTH'!E4 -> 0.20179889 | G15: ='YOY GROWTH'!F10/'YOY GROWTH'!F4 -> 0.19028606 | J15: Average GPM Growth | M15: Average ICR
B16: NPM | C16: ='YOY GROWTH'!B18/'YOY GROWTH'!B4 -> 0.14193743 | D16: ='YOY GROWTH'!C18/'YOY GROWTH'!C4 -> 0.1079352 | E16: ='YOY GROWTH'!D18/'YOY GROWTH'!D4 -> 0.1193929 | F16: ='YOY GROWTH'!E18/'YOY GROWTH'!E4 -> 0.12777599 | G16: ='YOY GROWTH'!F18/'YOY GROWTH'!F4 -> 0.12280892 | J16: =AVERAGE(D14:G14) -> 0.42772672 | M16: =AVERAGE(C17:G17) -> 19.38007
B17: Interest Coverage Ratio | C17: ='YOY GROWTH'!B12/'YOY GROWTH'!B13 -> 23.663751 | D17: ='YOY GROWTH'!C12/'YOY GROWTH'!C13 -> 15.412017 | E17: ='YOY GROWTH'!D12/'YOY GROWTH'!D13 -> 16.681609 | F17: ='YOY GROWTH'!E12/'YOY GROWTH'!E13 -> 18.802195 | G17: ='YOY GROWTH'!F12/'YOY GROWTH'!F13 -> 22.340778 | Q17: Row Labels | R17: Sum of Revenue Yoy Growth | S17: Sum of EBITDA Yoy Growth | T17: Sum of PAT yoy Growth
Q18: 44256
Q19: 44621 | R19: 0.076134999 | S19: -0.14096295 | T19: -0.18008636
Q20: 44986 | R20: 0.15310202 | S20: 0.25674204 | T20: 0.27561365 | Y20: Row Labels | Z20: Sum of Reserves YOY Growth | AA20: Sum of Debt YOY Growth
B21: Ratios | Q21: 45352 | R21: 0.028754858 | S21: 0.11069099 | T21: 0.10592618 | Y21: 44256
Q22: 45717 | R22: 0.069973231 | S22: 0.0089302073 | T22: 0.034144587 | Y22: 44621 | Z22: -0.28 | AA22: -0.054510197
B23: Particulars | C23: 44256 | D23: 44621 | E23: 44986 | F23: 45352 | G23: Mar 25 | H23: Trend | Q23: Grand Total | R23: 0.32796511 | S23: 0.23540029 | T23: 0.23559806 | Y23: 44986 | Z23: 0.39 | AA23: 1.1949391 | AB23: Row Labels | AC23: Sum of Debt to Equity
B24: Reserves to NCL | C24: 5.1630332 | D24: 3.8288683 | E24: 2.122468 | F24: 3.273069 | G24: 4.3126797 | Y24: 45352 | Z24: 0.12 | AA24: -0.41698673 | AB24: 44256 | AC24: 29.594853
B25: Reserves YOY Growth | D25: =('BALANCE C'!C12-'BALANCE C'!B12)/'BALANCE C'!B12 -> -0.27505886 | E25: =('BALANCE C'!D12-'BALANCE C'!C12)/'BALANCE C'!C12 -> 0.38522737 | F25: =('BALANCE C'!E12-'BALANCE C'!D12)/'BALANCE C'!D12 -> 0.11601969 | G25: =('BALANCE C'!F12-'BALANCE C'!E12)/'BALANCE C'!E12 -> 0.10573258 | Y25: 45717 | Z25: 0.11 | AA25: -0.21197719 | AB25: 44621 | AC25: 37.555832
B26: Debt to Equity | C26: 29.594853 | D26: 37.555832 | E26: 64.41677 | F26: 29.347862 | G26: 31.039851 | Q26: Year | R26: Reserves YOY Growth | S26: Debt YOY Growth | Y26: Grand Total | Z26: 0.34 | AA26: 0.511465 | AB26: 44986 | AC26: 64.41677
B27: Current Ratio | C27: 1.081647 | D27: 1.1871139 | E27: 1.1479852 | F27: 0.95540856 | G27: 1.2228417 | Q27: 44256 | T27: Row Labels | U27: Sum of EBITDAM YOY Growth | V27: Row Labels | W27: Sum of Current Ratio | X27: Sum of Quick Ratio | AB27: 45352 | AC27: 29.347862
B28: Quick Ratio | C28: 0.73990537 | D28: 0.89791182 | E28: 0.85936774 | F28: 0.62634724 | G28: 0.92084709 | Q28: 44621 | R28: -0.28 | S28: -0.054510197 | T28: 44256 | U28: 0.21483937 | V28: 44256 | W28: 1.081647 | X28: 0.73990537 | AB28: 45717 | AC28: 31.039851
B29: Days Receivables | C29: 12.709939 | D29: 10.295364 | E29: 7.5110323 | F29: 7.3221874 | G29: 5.3552006 | Q29: 44986 | R29: 0.39 | S29: 1.1949391 | T29: 44621 | U29: 0.17149798 | V29: 44621 | W29: 1.1871139 | X29: 0.89791182 | AB29: Grand Total | AC29: 191.95517
B30: Days Payables | C30: 83.865141 | D30: 67.809344 | E30: 55.13493 | F30: 49.420967 | G30: 45.254761 | Q30: 45352 | R30: 0.12 | S30: -0.41698673 | T30: 44986 | U30: 0.1869121 | V30: 44986 | W30: 1.1479852 | X30: 0.85936774
B31: Inventory Turnover Ratio | C31: 10.623561 | D31: 11.967508 | E31: 13.660518 | F31: 12.26281 | G31: 16.438694 | Q31: 45717 | R31: 0.11 | S31: -0.21197719 | T31: 45352 | U31: 0.20179889 | V31: 45352 | W31: 0.95540856 | X31: 0.62634724 | AI31: Row Labels | AJ31: Sum of Days Receivables | AK31: Sum of Days Payables
B32: Debtor Turnover Ratio | C32: 29.281871 | D32: 35.939949 | E32: 49.554782 | F32: 50.520501 | G32: 69.742566 | T32: 45717 | U32: 0.19028606 | V32: 45717 | W32: 1.2228417 | X32: 0.92084709 | AI32: 44256 | AJ32: 12.709939 | AK32: 83.865141
B33: Creditor Turnover Ratio | C33: 4.3522254 | D33: 5.382739 | E33: 6.6201227 | F33: 7.3855293 | G33: 8.0654497 | T33: Grand Total | U33: 0.96533439 | V33: Grand Total | W33: 5.5949963 | X33: 4.0443793 | AI33: 44621 | AJ33: 10.295364 | AK33: 67.809344
AI34: 44986 | AJ34: 7.5110323 | AK34: 55.13493
B35: Cash Flow Statement | AI35: 45352 | AJ35: 7.3221874 | AK35: 49.420967
B36: Particulars | C36: 44256 | D36: 44621 | E36: 44986 | F36: 45352 | G36: Mar 25 | H36: Trend | AI36: 45717 | AJ36: 5.3552006 | AK36: 45.254761
B37: =CFS!A3 -> Cash from Operating Activity | C37: =CFS!B3 -> 1876 | D37: =CFS!C3 -> 1300 | E37: =CFS!D3 -> 2526 | F37: =CFS!E3 -> 2573 | G37: =CFS!F3 -> 2481 | AI37: Grand Total | AJ37: 43.193723 | AK37: 301.48514
B38: =CFS!A4 -> Cash from Investing Activity | C38: =CFS!B4 -> 433 | D38: =CFS!C4 -> 914 | E38: =CFS!D4 -> -1507 | F38: =CFS!E4 -> 485 | G38: =CFS!F4 -> 87
B39: =CFS!A5 -> Cash from Financing Activity | C39: =CFS!B5 -> -2242 | D39: =CFS!C5 -> -2246 | E39: =CFS!D5 -> -1028 | F39: =CFS!E5 -> -2839 | G39: =CFS!F5 -> -2762
B40: =CFS!A6 -> Net Cash Flow | C40: =CFS!B6 -> 66 | D40: =CFS!C6 -> -32 | E40: =CFS!D6 -> -9 | F40: =CFS!E6 -> 219 | G40: =CFS!F6 -> -194
B44: Analysis of Cash flow statement
B45: Particulars | C45: 44256 | D45: 44621 | E45: 44986 | F45: 45352 | G45: Mar 25 | H45: Trend
B46: CFO YOY Growth | D46: =(D37-C37)/C37 -> -0.30703625 | E46: =(E37-D37)/D37 -> 0.94307692 | F46: =(F37-E37)/E37 -> 0.018606492 | G46: =(G37-F37)/F37 -> -0.035755927
B47: CFI YOY Growth | D47: =(D38-C38)/C38 -> 1.1108545 | E47: =(E38-D38)/D38 -> -2.6487965 | F47: =(F38-E38)/E38 -> -1.3218315 | G47: =(G38-F38)/F38 -> -0.82061856
B48: CFF YOY Growth | D48: =(D39-C39)/C39 -> 0.0017841213 | E48: =(E39-D39)/D39 -> -0.54229742 | F48: =(F39-E39)/E39 -> 1.7616732 | G48: =(G39-F39)/F39 -> -0.027122226
B49: Net Cash Flow Growth | D49: =(D40-C40)/C40 -> -1.4848485 | E49: =(E40-D40)/D40 -> -0.71875 | F49: =(F40-E40)/E40 -> -25.333333 | G49: =(G40-F40)/F40 -> -1.8858447
B50: Average CFO | G50: =AVERAGE(C37:G37) -> 2151.2
...

Sheet one pager
B1: BRITANNIA INDUSTRIES LTD.
B9: Analysis | J9: Average NPM Growth | M9: Average EBITDAM Growth
B10: Particular | C10: 44256 | D10: 44621 | E10: 44986 | F10: 45352 | G10: 45717 | H10: Trend | J10: =AVERAGE(C16:G16) -> 0.12397009 | M10: =AVERAGE(C15:G15) -> 0.19306688
B11: Revenue YoY Growth | D11: =('YOY GROWTH'!C4-'YOY GROWTH'!B4)/'YOY GROWTH'!B4 -> 0.076134999 | E11: =('YOY GROWTH'!D4-'YOY GROWTH'!C4)/'YOY GROWTH'!C4 -> 0.15310202 | F11: =('YOY GROWTH'!E4-'YOY GROWTH'!D4)/'YOY GROWTH'!D4 -> 0.028754858 | G11: =('YOY GROWTH'!F4-'YOY GROWTH'!E4)/'YOY GROWTH'!E4 -> 0.069973231
B12: EBITDA YoY Growth | D12: =('YOY GROWTH'!C10-'YOY GROWTH'!B10)/'YOY GROWTH'!B10 -> -0.14096295 | E12: =('YOY GROWTH'!D10-'YOY GROWTH'!C10)/'YOY GROWTH'!C10 -> 0.25674204 | F12: =('YOY GROWTH'!E10-'YOY GROWTH'!D10)/'YOY GROWTH'!D10 -> 0.11069099 | G12: =('YOY GROWTH'!F10-'YOY GROWTH'!E10)/'YOY GROWTH'!E10 -> 0.0089302073
B13: PAT yoy Growth | D13: =('YOY GROWTH'!C16-'YOY GROWTH'!B16)/'YOY GROWTH'!B16 -> -0.18008636 | E13: =('YOY GROWTH'!D16-'YOY GROWTH'!C16)/'YOY GROWTH'!C16 -> 0.27561365 | F13: =('YOY GROWTH'!E16-'YOY GROWTH'!D16)/'YOY GROWTH'!D16 -> 0.10592618 | G13: =('YOY GROWTH'!F16-'YOY GROWTH'!E16)/'YOY GROWTH'!E16 -> 0.034144587
B14: Gross Profit Margin | D14: ='YOY GROWTH'!B8/'YOY GROWTH'!B4 -> 0.44327405 | E14: ='YOY GROWTH'!C8/'YOY GROWTH'!C4 -> 0.39605879 | F14: ='YOY GROWTH'!D8/'YOY GROWTH'!D4 -> 0.42483904 | G14: ='YOY GROWTH'!E8/'YOY GROWTH'!E4 -> 0.44673501
B15: EBITDAM YOY Growth | C15: ='YOY GROWTH'!B10/'YOY GROWTH'!B4 -> 0.21483937 | D15: ='YOY GROWTH'!C10/'YOY GROWTH'!C4 -> 0.17149798 | E15: ='YOY GROWTH'!D10/'YOY GROWTH'!D4 -> 0.1869121 | F15: ='YOY GROWTH'!E10/'YOY GROWTH'!E4 -> 0.20179889 | G15: ='YOY GROWTH'!F10/'YOY GROWTH'!F4 -> 0.19028606 | J15: Average GPM Growth | M15: Average ICR
B16: NPM | C16: ='YOY GROWTH'!B18/'YOY GROWTH'!B4 -> 0.14193743 | D16: ='YOY GROWTH'!C18/'YOY GROWTH'!C4 -> 0.1079352 | E16: ='YOY GROWTH'!D18/'YOY GROWTH'!D4 -> 0.1193929 | F16: ='YOY GROWTH'!E18/'YOY GROWTH'!E4 -> 0.12777599 | G16: ='YOY GROWTH'!F18/'YOY GROWTH'!F4 -> 0.12280892 | J16: =AVERAGE(D14:G14) -> 0.42772672 | M16: =AVERAGE(C17:G17) -> 19.38007
B17: Interest Coverage Ratio | C17: ='YOY GROWTH'!B12/'YOY GROWTH'!B13 -> 23.663751 | D17: ='YOY GROWTH'!C12/'YOY GROWTH'!C13 -> 15.412017 | E17: ='YOY GROWTH'!D12/'YOY GROWTH'!D13 -> 16.681609 | F17: ='YOY GROWTH'!E12/'YOY GROWTH'!E13 -> 18.802195 | G17: ='YOY GROWTH'!F12/'YOY GROWTH'!F13 -> 22.340778
B21: Ratios
B23: Particulars | C23: 44256 | D23: 44621 | E23: 44986 | F23: 45352 | G23: Mar 25 | H23: Trend
B24: Reserves to NCL | C24: 5.1630332 | D24: 3.8288683 | E24: 2.122468 | F24: 3.273069 | G24: 4.3126797
B25: Reserves YOY Growth | D25: =('BALANCE C'!C12-'BALANCE C'!B12)/'BALANCE C'!B12 -> -0.27505886 | E25: =('BALANCE C'!D12-'BALANCE C'!C12)/'BALANCE C'!C12 -> 0.38522737 | F25: =('BALANCE C'!E12-'BALANCE C'!D12)/'BALANCE C'!D12 -> 0.11601969 | G25: =('BALANCE C'!F12-'BALANCE C'!E12)/'BALANCE C'!E12 -> 0.10573258
B26: Debt to Equity | C26: 29.594853 | D26: 37.555832 | E26: 64.41677 | F26: 29.347862 | G26: 31.039851
B27: Debt YOY Growth | D27: =('BALANCE C'!C17-'BALANCE C'!B17)/'BALANCE C'!B17 -> -0.054510197 | E27: =('BALANCE C'!D17-'BALANCE C'!C17)/'BALANCE C'!C17 -> 1.1949391 | F27: =('BALANCE C'!E17-'BALANCE C'!D17)/'BALANCE C'!D17 -> -0.41698673 | G27: =('BALANCE C'!F17-'BALANCE C'!E17)/'BALANCE C'!E17 -> -0.21197719
B28: Current Ratio | C28: 1.081647 | D28: 1.1871139 | E28: 1.1479852 | F28: 0.95540856 | G28: 1.2228417
B29: Quick Ratio | C29: 0.73990537 | D29: 0.89791182 | E29: 0.85936774 | F29: 0.62634724 | G29: 0.92084709
B30: Days Receivables | C30: 12.709939 | D30: 10.295364 | E30: 7.5110323 | F30: 7.3221874 | G30: 5.3552006
B31: Days Payables | C31: 83.865141 | D31: 67.809344 | E31: 55.13493 | F31: 49.420967 | G31: 45.254761
B32: Inventory Turnover Ratio | C32: 10.623561 | D32: 11.967508 | E32: 13.660518 | F32: 12.26281 | G32: 16.438694
B33: Debtor Turnover Ratio | C33: 29.281871 | D33: 35.939949 | E33: 49.554782 | F33: 50.520501 | G33: 69.742566
B35: Creditor Turnover Ratio | C35: 4.3522254 | D35: 5.382739 | E35: 6.6201227 | F35: 7.3855293 | G35: 8.0654497
B37: Cash Flow Statement
B38: Particulars | C38: 44256 | D38: 44621 | E38: 44986 | F38: 45352 | G38: Mar 25 | H38: Trend
B39: =CFS!A3 -> Cash from Operating Activity | C39: =CFS!B3 -> 1876 | D39: =CFS!C3 -> 1300 | E39: =CFS!D3 -> 2526 | F39: =CFS!E3 -> 2573 | G39: =CFS!F3 -> 2481
B40: =CFS!A4 -> Cash from Investing Activity | C40: =CFS!B4 -> 433 | D40: =CFS!C4 -> 914 | E40: =CFS!D4 -> -1507 | F40: =CFS!E4 -> 485 | G40: =CFS!F4 -> 87
B41: =CFS!A5 -> Cash from Financing Activity | C41: =CFS!B5 -> -2242 | D41: =CFS!C5 -> -2246 | E41: =CFS!D5 -> -1028 | F41: =CFS!E5 -> -2839 | G41: =CFS!F5 -> -2762
B42: =CFS!A6 -> Net Cash Flow | C42: =CFS!B6 -> 66 | D42: =CFS!C6 -> -32 | E42: =CFS!D6 -> -9 | F42: =CFS!E6 -> 219 | G42: =CFS!F6 -> -194
B46: Analysis of Cash flow statement
B47: Particulars | C47: 44256 | D47: 44621 | E47: 44986 | F47: 45352 | G47: Mar 25 | H47: Trend
B48: CFO YOY Growth | D48: =(D39-C39)/C39 -> -0.30703625 | E48: =(E39-D39)/D39 -> 0.94307692 | F48: =(F39-E39)/E39 -> 0.018606492 | G48: =(G39-F39)/F39 -> -0.035755927
B49: CFI YOY Growth | D49: =(D40-C40)/C40 -> 1.1108545 | E49: =(E40-D40)/D40 -> -2.6487965 | F49: =(F40-E40)/E40 -> -1.3218315 | G49: =(G40-F40)/F40 -> -0.82061856
B50: CFF YOY Growth | D50: =(D41-C41)/C41 -> 0.0017841213 | E50: =(E41-D41)/D41 -> -0.54229742 | F50: =(F41-E41)/E41 -> 1.7616732 | G50: =(G41-F41)/F41 -> -0.027122226
B51: Net Cash Flow Growth | D51: =(D42-C42)/C42 -> -1.4848485 | E51: =(E42-D42)/D42 -> -0.71875 | F51: =(F42-E42)/E42 -> -25.333333 | G51: =(G42-F42)/F42 -> -1.8858447
B52: Average CFO | G52: =AVERAGE(C39:G39) -> 2151.2
B53: Average CFI | G53: =AVERAGE(C40:G40) -> 82.4
B54: Average CFF | G54: =AVERAGE(C41:G41) -> -2223.4

Sheet WORKIN SHEET
A1: WORKING SHEET
A4: Year | B4: Revenue Yoy Growth | C4: EBITDA Yoy Growth | D4: PAT yoy Growth | E4: Gross Profit Margin | F4: EBITDAM YOY Growth | G4: NPM | H4: Interest Coverage Ratio
A5: 44256 | F5: 0.21483937 | G5: 0.14193743 | H5: 23.663751
A6: 44621 | B6: 0.076134999 | C6: -0.14096295 | D6: -0.18008636 | E6: 0.44327405 | F6: 0.17149798 | G6: 0.1079352 | H6: 15.412017
A7: 44986 | B7: 0.15310202 | C7: 0.25674204 | D7: 0.27561365 | E7: 0.39605879 | F7: 0.1869121 | G7: 0.1193929 | H7: 16.681609
A8: 45352 | B8: 0.028754858 | C8: 0.11069099 | D8: 0.10592618 | E8: 0.42483904 | F8: 0.20179889 | G8: 0.12777599 | H8: 18.802195
A9: 45717 | B9: 0.069973231 | C9: 0.0089302073 | D9: 0.034144587 | E9: 0.44673501 | F9: 0.19028606 | G9: 0.12280892 | H9: 22.340778
A11: Ratios
A13: Particulars | B13: 44256 | C13: 44621 | D13: 44986 | E13: 45352 | F13: Mar 25
A14: Reserves to NCL | B14: 5.1630332 | C14: 3.8288683 | D14: 2.122468 | E14: 3.273069 | F14: 4.3126797
A15: Debt to Equity | B15: 29.594853 | C15: 37.555832 | D15: 64.41677 | E15: 29.347862 | F15: 31.039851
A16: Current Ratio | B16: 1.081647 | C16: 1.1871139 | D16: 1.1479852 | E16: 0.95540856 | F16: 1.2228417
A17: Quick Ratio | B17: 0.73990537 | C17: 0.89791182 | D17: 0.85936774 | E17: 0.62634724 | F17: 0.92084709
A18: Days Receivables | B18: 12.709939 | C18: 10.295364 | D18: 7.5110323 | E18: 7.3221874 | F18: 5.3552006
A19: Days Payables | B19: 83.865141 | C19: 67.809344 | D19: 55.13493 | E19: 49.420967 | F19: 45.254761
A20: Inventory Turnover Ratio | B20: 10.623561 | C20: 11.967508 | D20: 13.660518 | E20: 12.26281 | F20: 16.438694
A21: Debtor Turnover Ratio | B21: 29.281871 | C21: 35.939949 | D21: 49.554782 | E21: 50.520501 | F21: 69.742566
A22: Creditor Turnover Ratio | B22: 4.3522254 | C22: 5.382739 | D22: 6.6201227 | E22: 7.3855293 | F22: 8.0654497
K23: Gross Profit YOY Growth
A24: Revenue Yoy Growth
B25: Revenue Growth | K25: Row Labels | L25: Sum of Gross Profit Margin
B26: 44256 | C26: 44621 | D26: 44986 | E26: 45352 | F26: 45717 | G26: Grand Total | K26: 44256
A27: Sum of Revenue Yoy Growth | C27: 0.076134999 | D27: 0.15310202 | E27: 0.028754858 | F27: 0.069973231 | G27: 0.32796511 | K27: 44621 | L27: 0.44327405
K28: 44986 | L28: 0.39605879
K29: 45352 | L29: 0.42483904
K30: 45717 | L30: 0.44673501
K31: Grand Total | L31: 1.7109069
K39: EBITDAM YOY GROWTH
K41: Row Labels | L41: Sum of EBITDAM YOY Growth
K42: 44256 | L42: 0.21483937
K43: 44621 | L43: 0.17149798
A44: EBITDA Pivot | K44: 44986 | L44: 0.1869121
A45: Row Labels | B45: Sum of EBITDA Yoy Growth | K45: 45352 | L45: 0.20179889
A46: 44256 | K46: 45717 | L46: 0.19028606
A47: 44621 | B47: -0.14096295 | K47: Grand Total | L47: 0.96533439
A48: 44986 | B48: 0.25674204
A49: 45352 | B49: 0.11069099
A50: 45717 | B50: 0.0089302073
A51: Grand Total | B51: 0.23540029
K57: NPM YOY GROWTH
...

Sheet Sheet4
