Workbook

Sheet Notes
B2: VODAFONE IDEA LIMITED — WORKING CAPITAL DISTRESS ANALYSIS
B3: Financial journey FY2020-21 to FY2025-26, with Q1 FY2026-27 update | Figures corrected and re-sourced 16 September 2026 - see the Sources tab
B5: PURPOSE
B6: Objective | C6: Identify working-capital distress across a 5+ year financial journey and trace its impact on (a) working capital management, (b) investment decisions, and (c) financing decisions.
B7: Company | C7: Vodafone Idea Ltd (NSE: IDEA / BSE: 532822). Formed Aug-2018 from the merger of Vodafone India and Idea Cellular. India's third-largest wireless operator.
B8: Why this company | C8: A rare case where distress is legible: EBITDA margin above 40%, receivable days of 16, negligible inventory. The distress sits almost entirely on the CURRENT LIABILITY side and is statutory, not commercial, in origin. That isolates the transmission mechanism cleanly.
B9: HOW TO USE THIS WORKBOOK
B10: Colour convention | C10: BLUE text = hardcoded input (sourced data). BLACK text = formula computed on this sheet. GREEN text = link to another sheet. YELLOW fill = key assumption to review.
B11: Live model | C11: All ratios, totals and derived metrics are live formulas. Change any blue input and every dependent figure recalculates.
B12: Tabs | C12: Income Statement | Working Capital (the core decomposition) | Ratios (dashboard) | Investment | Investment Timeline (dated events with sources) | Financing | Findings | Sources (source register, by line item)
B13: DATA HEALTH WARNING — READ BEFORE CITING
B14: Source variance | C14: Reported figures for Vi differ across sources for three reasons: (1) standalone vs consolidated presentation (c.₹400-500 cr on revenue, ₹50-70 cr on PAT); (2) 'revenue from operations' vs 'total income'; (3) differing treatment of current maturities of long-term debt and lease liabilities inside current liabilities — which materially changes any computed working-capital figure.
B15: Definition used here | C15: Net Working Capital = Total Current Assets less Total Current Liabilities, INCLUDING current maturities of debt and statutory dues. Consolidated basis throughout.
B16: What changed | C16: This version replaces the earlier indicative reconstructions with published figures. Corrected: EBITDA, D&A, finance cost (previously mis-aligned by one year), operating cash flow (previously understated by roughly half in FY21-FY24), capex, net worth FY26, every current asset and current liability line, total assets and liabilities, CWIP, shareholding by year, and ARPU FY26. Removed for lack of a source: Bharti Airtel capex FY21-FY25, revenue market share, forward spectrum instalments, FY24 bank debt.
B17: Remaining gaps | C17: FY21 current asset / liability components are not split in the sources used, so only the audited totals are entered and FY21 composition ratios read n/a. Four rows are deliberately blank and flagged in-cell; fill them from the FY26 annual report and TRAI reports before submission.
B18: KEY SOURCES
B19: Primary | C19: Vodafone Idea Ltd (NSE: IDEA / BSE: 532822) quarterly results releases, investor presentations and annual reports.
B20: Regulatory | C20: Supreme Court orders of 27-Oct-2025 and 03-Nov-2025 on AGR reassessment; DoT committee order, April 2026 (AGR cut of ₹23,649 cr).
B21: Market/press | C21: Screener.in (C-MOTS data), stockanalysis.com (S&P Global Market Intelligence), Equitymaster annual report analyses, Business Standard, Zee Business, TelecomLead.
B22: Theory | C22: Myers (1977) debt overhang · Myers & Majluf (1984) pecking order · Altman (1968, rev. 1993) Z-score.
B23: DISCLAIMER
C24: Academic case analysis prepared for educational purposes. Not investment advice and no recommendation regarding Vodafone Idea securities.

Sheet Charts
S1: Helper data for Chart 2 benchmark line (1.00x) — do not delete
B2: Chart Pack — Vodafone Idea Working Capital Distress Analysis | S2: 1
B3: All charts are native, live-linked Excel objects sourced directly from the Income Statement, Working Capital, Ratios, Investment and Financing tabs. Change any blue input on those tabs and every chart below updates automatically. | S3: 1
S4: 1
S5: 1
S6: 1
S7: 1

Sheet Income Statement
B2: Income Statement & Cash Flow Summary
B3: Consolidated, ₹ crore. Blue = input, black = formula. FY26 net profit is inflated by a one-off AGR write-back.
B5: ₹ crore (consolidated) | C5: FY21 | D5: FY22 | E5: FY23 | F5: FY24 | G5: FY25 | H5: FY26
B6: OPERATING PERFORMANCE
B7: Revenue from operations | C7: 41952 | D7: 38516 | E7: 42177 | F7: 42652 | G7: 43572 | H7: 44873
B8: Growth (% YoY) | D8: =IF(D7=0,0,D7/OFFSET(D7,0,-1)-1) -> -0.081903127 | E8: =IF(E7=0,0,E7/OFFSET(E7,0,-1)-1) -> 0.095051407 | F8: =IF(F7=0,0,F7/OFFSET(F7,0,-1)-1) -> 0.011262062 | G8: =IF(G7=0,0,G7/OFFSET(G7,0,-1)-1) -> 0.021569915 | H8: =IF(H7=0,0,H7/OFFSET(H7,0,-1)-1) -> 0.029858625
B9: EBITDA | C9: 16946 | D9: 15968 | E9: 16753 | F9: 17072 | G9: 18048 | H9: 18859 | J9: Consolidated operating profit, C-MOTS via Screener (NSE: IDEA). Company-reported EBITDA differs slightly on presentation: FY25 Rs 18,127 cr, FY26 Rs 19,003 cr.
B10: EBITDA margin (%) | C10: =IF(C7=0,0,C9/C7) -> 0.40393783 | D10: =IF(D7=0,0,D9/D7) -> 0.41458095 | E10: =IF(E7=0,0,E9/E7) -> 0.39720701 | F10: =IF(F7=0,0,F9/F7) -> 0.40026259 | G10: =IF(G7=0,0,G9/G7) -> 0.41421096 | H10: =IF(H7=0,0,H9/H7) -> 0.420275
B11: Depreciation & amortisation | C11: 23638 | D11: 23584 | E11: 23050 | F11: 22634 | G11: 21973 | H11: 22108 | J11: Consolidated D&A, C-MOTS via Screener. Includes Ind AS 116 lease depreciation.
B12: EBIT | C12: =C9-C11 -> -6692 | D12: =D9-D11 -> -7616 | E12: =E9-E11 -> -6297 | F12: =F9-F11 -> -5562 | G12: =G9-G11 -> -3925 | H12: =H9-H11 -> -3249
B13: Finance cost | C13: 17998 | D13: 20981 | E13: 23354 | F13: 25766 | G13: 24543 | H13: 21495 | J13: Consolidated finance cost, C-MOTS via Screener. Prior version had this row mis-aligned by one year.
B14: Interest coverage (EBITDA / finance cost) | C14: =IF(C13=0,0,C9/C13) -> 0.94154906 | D14: =IF(D13=0,0,D9/D13) -> 0.76106954 | E14: =IF(E13=0,0,E9/E13) -> 0.71735035 | F14: =IF(F13=0,0,F9/F13) -> 0.66257859 | G14: =IF(G13=0,0,G9/G13) -> 0.73536243 | H14: =IF(H13=0,0,H9/H13) -> 0.87736683 | J14: <1.00x in EVERY year: operating profit never covered interest
B16: PROFITABILITY
B17: Loss before exceptional items | C17: -44233 | D17: -28245 | E17: -29301 | F17: -31238 | G17: -27384 | H17: -22939 | J17: FY26 pre-exceptional loss = sum of the four reported quarterly results less the Q4 exceptional gain.
B18: Exceptional items | C18: 0 | D18: 0 | E18: 0 | F18: 0 | G18: 0 | H18: 57491 | J18: FY26: Rs 57,491 cr exceptional gain on DoT reassessment of AGR dues, recognised in Q4 FY26 (company results release, 16-May-2026). Reconciles -22,939 to reported PAT of 34,552.
B19: Net profit / (loss) | C19: =C17+C18 -> -44233 | D19: =D17+D18 -> -28245 | E19: =E17+E18 -> -29301 | F19: =F17+F18 -> -31238 | G19: =G17+G18 -> -27384 | H19: =H17+H18 -> 34552
B20: Net margin (%) | C20: =IF(C7=0,0,C19/C7) -> -1.0543717 | D20: =IF(D7=0,0,D19/D7) -> -0.7333316 | E20: =IF(E7=0,0,E19/E7) -> -0.69471513 | F20: =IF(F7=0,0,F19/F7) -> -0.73239238 | G20: =IF(G7=0,0,G19/G7) -> -0.628477 | H20: =IF(H7=0,0,H19/H7) -> 0.76999532
B21: Net worth (shareholders' funds) | C21: -38228 | D21: -61965 | E21: -74359 | F21: -104167 | G21: -70320 | H21: -35758 | J21: Equity capital + reserves per consolidated balance sheet. Negative throughout — technically insolvent on a book basis.
B23: CASH FLOW
B24: Cash flow from operations | C24: 15640 | D24: 17387 | E24: 18869 | F24: 20826 | G24: 9290 | H24: 19411 | J24: Audited consolidated cash flow statements. Prior version understated FY21-FY24 by roughly half.
B25: Capital expenditure | C25: 5106 | D25: 5992 | E25: 5537 | F25: 1530 | G25: 10220 | H25: 10814 | J25: Cash outflow on fixed assets per the consolidated cash flow statement (CFO less free cash flow, Screener). Company-disclosed capex is stated on a slightly different basis: FY26 Rs 8,742 cr.
B26: Free cash flow (CFO less capex) | C26: =C24-C25 -> 10534 | D26: =D24-D25 -> 11395 | E26: =E24-E25 -> 13332 | F26: =F24-F25 -> 19296 | G26: =G24-G25 -> -930 | H26: =H24-H25 -> 8597
B27: FCF less finance cost (true cash gap) | C27: =C26-C13 -> -7464 | D27: =D26-D13 -> -9586 | E27: =E26-E13 -> -10022 | F27: =F26-F13 -> -6470 | G27: =G26-G13 -> -25473 | H27: =H26-H13 -> -12898 | J27: The annual hole that had to be plugged by forbearance or new capital
B29: OPERATING DRIVERS
B30: Subscribers (million) | C30: 267.8 | D30: 243.8 | E30: 225.9 | F30: 212.6 | G30: 198.2 | H30: 192.8
B31: Net adds (million) | D31: =IF(COLUMN()=3,0,D30-OFFSET(D30,0,-1)) -> -24 | E31: =IF(COLUMN()=3,0,E30-OFFSET(E30,0,-1)) -> -17.9 | F31: =IF(COLUMN()=3,0,F30-OFFSET(F30,0,-1)) -> -13.3 | G31: =IF(COLUMN()=3,0,G30-OFFSET(G30,0,-1)) -> -14.4 | H31: =IF(COLUMN()=3,0,H30-OFFSET(H30,0,-1)) -> -5.4
B32: ARPU (₹ per month) | C32: 107 | D32: 124 | E32: 135 | F32: 146 | G32: 175 | H32: 190 | J32: Q4 exit customer ARPU (ex-M2M) per quarterly results releases. Q1 FY27: Rs 195.
B33: ARPU growth (%) | D33: =IF(COLUMN()=3,0,IF(OFFSET(D32,0,-1)=0,0,D32/OFFSET(D32,0,-1)-1)) -> 0.1588785 | E33: =IF(COLUMN()=3,0,IF(OFFSET(E32,0,-1)=0,0,E32/OFFSET(E32,0,-1)-1)) -> 0.088709677 | F33: =IF(COLUMN()=3,0,IF(OFFSET(F32,0,-1)=0,0,F32/OFFSET(F32,0,-1)-1)) -> 0.081481481 | G33: =IF(COLUMN()=3,0,IF(OFFSET(G32,0,-1)=0,0,G32/OFFSET(G32,0,-1)-1)) -> 0.19863014 | H33: =IF(COLUMN()=3,0,IF(OFFSET(H32,0,-1)=0,0,H32/OFFSET(H32,0,-1)-1)) -> 0.085714286
B35: Note: Q4 exit ARPU rose 78% (Rs 107 to Rs 190) and the EBITDA margin gained about 2 points across the period — yet solvency did not improve until liabilities were restructured.

Sheet Working Capital
B2: Working Capital Decomposition
B3: The central diagnostic. Negative working capital is NORMAL in prepaid telecom — the question is what makes it negative.
B5: ₹ crore (consolidated) | C5: FY21 | D5: FY22 | E5: FY23 | F5: FY24 | G5: FY25 | H5: FY26
B6: CURRENT ASSETS
B7: Inventories | D7: 2 | E7: 16 | F7: 1 | G7: 1 | H7: 21 | J7: Prior version overstated inventory 10x by reading Rs million as Rs crore.
B8: Trade receivables | D8: 2444 | E8: 2164 | F8: 2195 | G8: 2000 | H8: 1969
B9: Cash & cash equivalents | D9: 1453 | E9: 229 | F9: 168 | G9: 257 | H9: 2106
B10: Short-term investments | D10: 6 | E10: 6 | F10: 1 | G10: 6053 | H10: 1609
B11: Other current assets | D11: 12930 | E11: 11486 | F11: 10545 | G11: 22728 | H11: 16171 | J11: Other receivables + prepaid expenses + other current assets.
B12: Total current assets | C12: 14100 | D12: =SUM(D7:D11) -> 16835 | E12: =SUM(E7:E11) -> 13901 | F12: =SUM(F7:F11) -> 12910 | G12: =SUM(G7:G11) -> 31039 | H12: =SUM(H7:H11) -> 21876 | J12: FY21 total is an audited aggregate (Rs 140,995 mn); the component split is not in the sources used, so FY21 composition ratios are marked n/a.
B14: CURRENT LIABILITIES
B15: Trade payables | D15: 13170 | E15: 13536 | F15: 13436 | G15: 10747 | H15: 8826 | J15: Trade payables only. The prior version bundled accruals and other items into this row, inflating DPO.
B16: Current maturities of debt & statutory dues | D16: 26378 | E16: 23415 | F16: 16588 | G16: 21244 | H16: 10559 | J16: Short-term borrowings + current maturities of long-term debt + current lease liabilities. Peaks at 43% of current liabilities in FY22.
B17: Other current liabilities & provisions | D17: 21586 | E17: 23072 | F17: 24118 | G17: 23623 | H17: 20304 | J17: Accrued expenses + current tax + unearned revenue + other current liabilities and provisions.
B18: Total current liabilities | C18: 66403 | D18: =SUM(D15:D17) -> 61134 | E18: =SUM(E15:E17) -> 60023 | F18: =SUM(F15:F17) -> 54142 | G18: =SUM(G15:G17) -> 55614 | H18: =SUM(H15:H17) -> 39689 | J18: FY22 total was overstated by Rs 4,866 cr and FY26 by Rs 8,187 cr in the prior version.
B20: NET WORKING CAPITAL
B21: Net working capital (TCA less TCL) | C21: =C12-C18 -> -52303 | D21: =D12-D18 -> -44299 | E21: =E12-E18 -> -46122 | F21: =F12-F18 -> -41232 | G21: =G12-G18 -> -24575 | H21: =H12-H18 -> -17813 | J21: Negative in all six years
B22: as % of revenue | C22: =IF('Income Statement'!C7=0,0,C21/'Income Statement'!C7) -> -1.2467344 | D22: =IF('Income Statement'!D7=0,0,D21/'Income Statement'!D7) -> -1.1501454 | E22: =IF('Income Statement'!E7=0,0,E21/'Income Statement'!E7) -> -1.0935344 | F22: =IF('Income Statement'!F7=0,0,F21/'Income Statement'!F7) -> -0.96670731 | G22: =IF('Income Statement'!G7=0,0,G21/'Income Statement'!G7) -> -0.564009 | H22: =IF('Income Statement'!H7=0,0,H21/'Income Statement'!H7) -> -0.39696477
B23: YoY change in NWC | D23: =IF(COLUMN()=3,0,D21-OFFSET(D21,0,-1)) -> 8004 | E23: =IF(COLUMN()=3,0,E21-OFFSET(E21,0,-1)) -> -1823 | F23: =IF(COLUMN()=3,0,F21-OFFSET(F21,0,-1)) -> 4890 | G23: =IF(COLUMN()=3,0,G21-OFFSET(G21,0,-1)) -> 16657 | H23: =IF(COLUMN()=3,0,H21-OFFSET(H21,0,-1)) -> 6762 | J23: Every improvement maps to a financing event, not an operating one.
B25: WHY IT IS NEGATIVE — COMPOSITION TEST
B26: Current maturities as % of total CL | C26: ="n/a" -> n/a | D26: =IF(D18=0,0,D16/D18) -> 0.43147839 | E26: =IF(E18=0,0,E16/E18) -> 0.39010046 | F26: =IF(F18=0,0,F16/F18) -> 0.30637952 | G26: =IF(G18=0,0,G16/G18) -> 0.38199015 | H26: =IF(H18=0,0,H16/H18) -> 0.26604349 | J26: Statutory / debt maturities, not trade terms. Peak 43.1% of current liabilities (FY22).
B27: Trade payables as % of total CL | C27: ="n/a" -> n/a | D27: =IF(D18=0,0,D15/D18) -> 0.2154284 | E27: =IF(E18=0,0,E15/E18) -> 0.22551355 | F27: =IF(F18=0,0,F15/F18) -> 0.24816224 | G27: =IF(G18=0,0,G15/G18) -> 0.19324271 | H27: =IF(H18=0,0,H15/H18) -> 0.222379
B28: Receivables as % of total CA | C28: ="n/a" -> n/a | D28: =IF(D12=0,0,D8/D12) -> 0.14517375 | E28: =IF(E12=0,0,E8/E12) -> 0.15567225 | F28: =IF(F12=0,0,F8/F12) -> 0.17002324 | G28: =IF(G12=0,0,G8/G12) -> 0.064435066 | H28: =IF(H12=0,0,H8/H12) -> 0.090007314
B29: Liquid assets (cash + ST inv.) | C29: ="n/a" -> n/a | D29: =D9+D10 -> 1459 | E29: =E9+E10 -> 235 | F29: =F9+F10 -> 169 | G29: =G9+G10 -> 6310 | H29: =H9+H10 -> 3715
B30: Liquid assets as months of cash opex | C30: ="n/a" -> n/a | D30: =IF(('Income Statement'!D7-'Income Statement'!D9)=0,0,D29/(('Income Statement'!D7-'Income Statement'!D9)/12)) -> 0.77647685 | E30: =IF(('Income Statement'!E7-'Income Statement'!E9)=0,0,E29/(('Income Statement'!E7-'Income Statement'!E9)/12)) -> 0.11091882 | F30: =IF(('Income Statement'!F7-'Income Statement'!F9)=0,0,F29/(('Income Statement'!F7-'Income Statement'!F9)/12)) -> 0.079280688 | G30: =IF(('Income Statement'!G7-'Income Statement'!G9)=0,0,G29/(('Income Statement'!G7-'Income Statement'!G9)/12)) -> 2.9666197 | H30: =IF(('Income Statement'!H7-'Income Statement'!H9)=0,0,H29/(('Income Statement'!H7-'Income Statement'!H9)/12)) -> 1.7136926 | J30: FY24: about 2.4 days of cash operating cost on hand.
B32: DIAGNOSIS
B33: - Receivables are NOT the problem - DSO fell from 23 days (FY22) to 16 days (FY26) as revenue rose. Prepaid customers pay before consuming service.
B34: - Inventory is NOT the problem - it never exceeds Rs 21 cr against Rs 44,873 cr of revenue.
B35: - The deficit is entirely liability-side, in two parts: (1) STATUTORY - current maturities of deferred spectrum, AGR dues and lease liabilities, at their FY22 peak 43% of all current liabilities; (2) COMMERCIAL BUT INVOLUNTARY - trade payable days of 213 in FY22, i.e. vendors paid roughly seven months late, easing to 124 days by FY26 as arrears were cleared.
B36: - Carrying payables at seven months is not working-capital management. It is the involuntary financing of an operating deficit by counterparties who cannot walk away. The unwind from 213 to 124 days tracks the equity conversions, not any negotiated change in trade terms.

Sheet Ratios
B2: Liquidity, Efficiency & Distress Ratios
B3: All cells are formulas linking to the Income Statement and Working Capital tabs (green = cross-sheet link).
B5: ₹ crore (consolidated) | C5: FY21 | D5: FY22 | E5: FY23 | F5: FY24 | G5: FY25 | H5: FY26
B6: LIQUIDITY
B7: Current ratio | C7: =IF('Working Capital'!C18=0,0,'Working Capital'!C12/'Working Capital'!C18) -> 0.2123398 | D7: =IF('Working Capital'!D18=0,0,'Working Capital'!D12/'Working Capital'!D18) -> 0.27537868 | E7: =IF('Working Capital'!E18=0,0,'Working Capital'!E12/'Working Capital'!E18) -> 0.23159456 | F7: =IF('Working Capital'!F18=0,0,'Working Capital'!F12/'Working Capital'!F18) -> 0.23844705 | G7: =IF('Working Capital'!G18=0,0,'Working Capital'!G12/'Working Capital'!G18) -> 0.55811486 | H7: =IF('Working Capital'!H18=0,0,'Working Capital'!H12/'Working Capital'!H18) -> 0.55118547 | J7: Healthy benchmark 1.5-2.0x. Vi never exceeds 0.56x.
B8: Quick ratio | C8: =IF('Working Capital'!C18=0,0,('Working Capital'!C12-'Working Capital'!C7)/'Working Capital'!C18) -> 0.2123398 | D8: =IF('Working Capital'!D18=0,0,('Working Capital'!D12-'Working Capital'!D7)/'Working Capital'!D18) -> 0.27534596 | E8: =IF('Working Capital'!E18=0,0,('Working Capital'!E12-'Working Capital'!E7)/'Working Capital'!E18) -> 0.23132799 | F8: =IF('Working Capital'!F18=0,0,('Working Capital'!F12-'Working Capital'!F7)/'Working Capital'!F18) -> 0.23842858 | G8: =IF('Working Capital'!G18=0,0,('Working Capital'!G12-'Working Capital'!G7)/'Working Capital'!G18) -> 0.55809688 | H8: =IF('Working Capital'!H18=0,0,('Working Capital'!H12-'Working Capital'!H7)/'Working Capital'!H18) -> 0.55065635
B9: Cash ratio | C9: ="n/a" -> n/a | D9: =IF('Working Capital'!D18=0,0,('Working Capital'!D9+'Working Capital'!D10)/'Working Capital'!D18) -> 0.023865607 | E9: =IF('Working Capital'!E18=0,0,('Working Capital'!E9+'Working Capital'!E10)/'Working Capital'!E18) -> 0.0039151659 | F9: =IF('Working Capital'!F18=0,0,('Working Capital'!F9+'Working Capital'!F10)/'Working Capital'!F18) -> 0.0031214214 | G9: =IF('Working Capital'!G18=0,0,('Working Capital'!G9+'Working Capital'!G10)/'Working Capital'!G18) -> 0.11346064 | H9: =IF('Working Capital'!H18=0,0,('Working Capital'!H9+'Working Capital'!H10)/'Working Capital'!H18) -> 0.093602761
B11: WORKING CAPITAL EFFICIENCY
B12: Receivable days (DSO) | C12: ="n/a" -> n/a | D12: =IF('Income Statement'!D7=0,0,'Working Capital'!D8/'Income Statement'!D7*365) -> 23.160764 | E12: =IF('Income Statement'!E7=0,0,'Working Capital'!E8/'Income Statement'!E7*365) -> 18.727268 | F12: =IF('Income Statement'!F7=0,0,'Working Capital'!F8/'Income Statement'!F7*365) -> 18.783996 | G12: =IF('Income Statement'!G7=0,0,'Working Capital'!G8/'Income Statement'!G7*365) -> 16.753879 | H12: =IF('Income Statement'!H7=0,0,'Working Capital'!H8/'Income Statement'!H7*365) -> 16.015978 | J12: Improving - asset side is efficient. FY21 debtor days were 22 per the FY21 annual report analysis.
B13: Inventory days (DIO) | C13: ="n/a" -> n/a | D13: =IF(('Income Statement'!D7-'Income Statement'!D9)=0,0,'Working Capital'!D7/('Income Statement'!D7-'Income Statement'!D9)*365) -> 0.032375377 | E13: =IF(('Income Statement'!E7-'Income Statement'!E9)=0,0,'Working Capital'!E7/('Income Statement'!E7-'Income Statement'!E9)*365) -> 0.22970422 | F13: =IF(('Income Statement'!F7-'Income Statement'!F9)=0,0,'Working Capital'!F7/('Income Statement'!F7-'Income Statement'!F9)*365) -> 0.01426896 | G13: =IF(('Income Statement'!G7-'Income Statement'!G9)=0,0,'Working Capital'!G7/('Income Statement'!G7-'Income Statement'!G9)*365) -> 0.014300266 | H13: =IF(('Income Statement'!H7-'Income Statement'!H9)=0,0,'Working Capital'!H7/('Income Statement'!H7-'Income Statement'!H9)*365) -> 0.29464904
B14: Payable days (DPO, on cash opex) | C14: ="n/a" -> n/a | D14: =IF(('Income Statement'!D7-'Income Statement'!D9)=0,0,'Working Capital'!D15/('Income Statement'!D7-'Income Statement'!D9)*365) -> 213.19186 | E14: =IF(('Income Statement'!E7-'Income Statement'!E9)=0,0,'Working Capital'!E15/('Income Statement'!E7-'Income Statement'!E9)*365) -> 194.32977 | F14: =IF(('Income Statement'!F7-'Income Statement'!F9)=0,0,'Working Capital'!F15/('Income Statement'!F7-'Income Statement'!F9)*365) -> 191.71775 | G14: =IF(('Income Statement'!G7-'Income Statement'!G9)=0,0,'Working Capital'!G15/('Income Statement'!G7-'Income Statement'!G9)*365) -> 153.68496 | H14: =IF(('Income Statement'!H7-'Income Statement'!H9)=0,0,'Working Capital'!H15/('Income Statement'!H7-'Income Statement'!H9)*365) -> 123.83678 | J14: Trade payable days: 213 in FY22 falling to 124 by FY26.
B15: Cash conversion cycle (DSO+DIO-DPO) | C15: ="n/a" -> n/a | D15: =D12+D13-D14 -> -189.99872 | E15: =E12+E13-E14 -> -175.37279 | F15: =F12+F13-F14 -> -172.91948 | G15: =G12+G13-G14 -> -136.91678 | H15: =H12+H13-H14 -> -107.52615 | J15: Deeply negative throughout, but it reflects inability to pay rather than negotiated terms.
B17: SOLVENCY & DISTRESS
B18: Interest coverage (EBITDA / finance cost) | C18: =IF('Income Statement'!C13=0,0,'Income Statement'!C9/'Income Statement'!C13) -> 0.94154906 | D18: =IF('Income Statement'!D13=0,0,'Income Statement'!D9/'Income Statement'!D13) -> 0.76106954 | E18: =IF('Income Statement'!E13=0,0,'Income Statement'!E9/'Income Statement'!E13) -> 0.71735035 | F18: =IF('Income Statement'!F13=0,0,'Income Statement'!F9/'Income Statement'!F13) -> 0.66257859 | G18: =IF('Income Statement'!G13=0,0,'Income Statement'!G9/'Income Statement'!G13) -> 0.73536243 | H18: =IF('Income Statement'!H13=0,0,'Income Statement'!H9/'Income Statement'!H13) -> 0.87736683 | J18: THE summary statistic: below 1.00x in all six years
B19: Cash interest gap (EBITDA less finance cost) | C19: ='Income Statement'!C9-'Income Statement'!C13 -> -1052 | D19: ='Income Statement'!D9-'Income Statement'!D13 -> -5013 | E19: ='Income Statement'!E9-'Income Statement'!E13 -> -6601 | F19: ='Income Statement'!F9-'Income Statement'!F13 -> -8694 | G19: ='Income Statement'!G9-'Income Statement'!G13 -> -6495 | H19: ='Income Statement'!H9-'Income Statement'!H13 -> -2636
B20: EBITDA / current liabilities | C20: =IF('Working Capital'!C18=0,0,'Income Statement'!C9/'Working Capital'!C18) -> 0.25519931 | D20: =IF('Working Capital'!D18=0,0,'Income Statement'!D9/'Working Capital'!D18) -> 0.26119672 | E20: =IF('Working Capital'!E18=0,0,'Income Statement'!E9/'Working Capital'!E18) -> 0.27910967 | F20: =IF('Working Capital'!F18=0,0,'Income Statement'!F9/'Working Capital'!F18) -> 0.31531898 | G20: =IF('Working Capital'!G18=0,0,'Income Statement'!G9/'Working Capital'!G18) -> 0.3245226 | H20: =IF('Working Capital'!H18=0,0,'Income Statement'!H9/'Working Capital'!H18) -> 0.47516944
B21: Net worth (₹ cr) | C21: ='Income Statement'!C21 -> -38228 | D21: ='Income Statement'!D21 -> -61965 | E21: ='Income Statement'!E21 -> -74359 | F21: ='Income Statement'!F21 -> -104167 | G21: ='Income Statement'!G21 -> -70320 | H21: ='Income Statement'!H21 -> -35758
B22: Operating cash flow / current liabilities | C22: =IF('Working Capital'!C18=0,0,'Income Statement'!C24/'Working Capital'!C18) -> 0.23553153 | D22: =IF('Working Capital'!D18=0,0,'Income Statement'!D24/'Working Capital'!D18) -> 0.28440802 | E22: =IF('Working Capital'!E18=0,0,'Income Statement'!E24/'Working Capital'!E18) -> 0.31436283 | F22: =IF('Working Capital'!F18=0,0,'Income Statement'!F24/'Working Capital'!F18) -> 0.38465517 | G22: =IF('Working Capital'!G18=0,0,'Income Statement'!G24/'Working Capital'!G18) -> 0.16704427 | H22: =IF('Working Capital'!H18=0,0,'Income Statement'!H24/'Working Capital'!H18) -> 0.48907758
B24: ALTMAN Z'' SCORE (non-manufacturer / emerging market)
B25: Z'' = 6.56·X1 + 3.26·X2 + 6.72·X3 + 1.05·X4
B26: Total assets (₹ cr) | C26: 203478 | D26: 194029 | E26: 207243 | F26: 184997 | G26: 197855 | H26: 191630 | J26: Consolidated total assets per published balance sheets (C-MOTS via Screener).
B27: Reserves & surplus (accumulated deficit) | C27: -66963 | D27: -94084 | E27: -123039 | F27: -154287 | G27: -141713 | H27: -144101 | J27: Total reserves per the consolidated balance sheet, used as the X2 proxy. Note this is net of securities premium, so it is smaller than the pure accumulated loss.
B28: Total liabilities (₹ cr) | C28: =C26-'Income Statement'!C21 -> 241706 | D28: =D26-'Income Statement'!D21 -> 255994 | E28: =E26-'Income Statement'!E21 -> 281602 | F28: =F26-'Income Statement'!F21 -> 289164 | G28: =G26-'Income Statement'!G21 -> 268175 | H28: =H26-'Income Statement'!H21 -> 227388 | J28: Computed as total assets less net worth, so it always ties to the balance sheet.
B29: X1 Working capital / total assets | C29: =IF(C26=0,0,'Working Capital'!C21/C26) -> -0.25704499 | D29: =IF(D26=0,0,'Working Capital'!D21/D26) -> -0.22831123 | E29: =IF(E26=0,0,'Working Capital'!E21/E26) -> -0.22255034 | F29: =IF(F26=0,0,'Working Capital'!F21/F26) -> -0.22287929 | G29: =IF(G26=0,0,'Working Capital'!G21/G26) -> -0.12420712 | H29: =IF(H26=0,0,'Working Capital'!H21/H26) -> -0.092955174
B30: X2 Retained earnings / total assets | C30: =IF(C26=0,0,C27/C26) -> -0.32909209 | D30: =IF(D26=0,0,D27/D26) -> -0.48489659 | E30: =IF(E26=0,0,E27/E26) -> -0.59369436 | F30: =IF(F26=0,0,F27/F26) -> -0.83399731 | G30: =IF(G26=0,0,G27/G26) -> -0.71624675 | H30: =IF(H26=0,0,H27/H26) -> -0.75197516
B31: X3 EBIT / total assets | C31: =IF(C26=0,0,'Income Statement'!C12/C26) -> -0.032888076 | D31: =IF(D26=0,0,'Income Statement'!D12/D26) -> -0.039251864 | E31: =IF(E26=0,0,'Income Statement'!E12/E26) -> -0.030384621 | F31: =IF(F26=0,0,'Income Statement'!F12/F26) -> -0.030065352 | G31: =IF(G26=0,0,'Income Statement'!G12/G26) -> -0.01983776 | H31: =IF(H26=0,0,'Income Statement'!H12/H26) -> -0.016954548
B32: X4 Book equity / total liabilities | C32: =IF(C28=0,0,'Income Statement'!C21/C28) -> -0.15815909 | D32: =IF(D28=0,0,'Income Statement'!D21/D28) -> -0.24205645 | E32: =IF(E28=0,0,'Income Statement'!E21/E28) -> -0.26405707 | F32: =IF(F28=0,0,'Income Statement'!F21/F28) -> -0.36023502 | G32: =IF(G28=0,0,'Income Statement'!G21/G28) -> -0.26221684 | H32: =IF(H28=0,0,'Income Statement'!H21/H28) -> -0.15725544
B33: Z'' score | C33: =6.56*C29+3.26*C30+6.72*C31+1.05*C32 -> -3.1461302 | D33: =6.56*D29+3.26*D30+6.72*D31+1.05*D32 -> -3.5964164 | E33: =6.56*E29+3.26*E30+6.72*E31+1.05*E32 -> -3.8768184 | F33: =6.56*F29+3.26*F30+6.72*F31+1.05*F32 -> -4.7612053 | G33: =6.56*G29+3.26*G30+6.72*G31+1.05*G32 -> -3.5584005 | H33: =6.56*H29+3.26*H30+6.72*H31+1.05*H32 -> -3.3402777 | J33: Distress zone is below 1.10. Vi is deeply negative in every year.
B34: Zone | C34: =IF(C33<1.1,"DISTRESS",IF(C33<2.6,"GREY","SAFE")) -> DISTRESS | D34: =IF(D33<1.1,"DISTRESS",IF(D33<2.6,"GREY","SAFE")) -> DISTRESS | E34: =IF(E33<1.1,"DISTRESS",IF(E33<2.6,"GREY","SAFE")) -> DISTRESS | F34: =IF(F33<1.1,"DISTRESS",IF(F33<2.6,"GREY","SAFE")) -> DISTRESS | G34: =IF(G33<1.1,"DISTRESS",IF(G33<2.6,"GREY","SAFE")) -> DISTRESS | H34: =IF(H33<1.1,"DISTRESS",IF(H33<2.6,"GREY","SAFE")) -> DISTRESS
B36: The Z-score is almost uninformative here precisely BECAUSE it is so extreme. It assumes arm's-length creditors. Vi's largest creditor was also its regulator and eventually its largest shareholder — which is why a model that classified the firm as failed for six straight years never predicted its actual outcome.

Sheet Investment
B2: Impact on Investment Decisions
B3: Capital budgeting ceased to be an NPV exercise and became a cash-availability exercise.
B5: ₹ crore (consolidated) | C5: FY21 | D5: FY22 | E5: FY23 | F5: FY24 | G5: FY25 | H5: FY26
B6: CAPITAL EXPENDITURE
B7: Capex (₹ cr) | C7: ='Income Statement'!C25 -> 5106 | D7: ='Income Statement'!D25 -> 5992 | E7: ='Income Statement'!E25 -> 5537 | F7: ='Income Statement'!F25 -> 1530 | G7: ='Income Statement'!G25 -> 10220 | H7: ='Income Statement'!H25 -> 10814
B8: Capex as % of revenue | C8: =IF('Income Statement'!C7=0,0,C7/'Income Statement'!C7) -> 0.12171053 | D8: =IF('Income Statement'!D7=0,0,D7/'Income Statement'!D7) -> 0.15557171 | E8: =IF('Income Statement'!E7=0,0,E7/'Income Statement'!E7) -> 0.13128008 | F8: =IF('Income Statement'!F7=0,0,F7/'Income Statement'!F7) -> 0.035871706 | G8: =IF('Income Statement'!G7=0,0,G7/'Income Statement'!G7) -> 0.2345543 | H8: =IF('Income Statement'!H7=0,0,H7/'Income Statement'!H7) -> 0.24099124 | J8: Sustaining capex in telecom is typically 15-20% of revenue
B9: Capex as % of EBITDA | C9: =IF('Income Statement'!C9=0,0,C7/'Income Statement'!C9) -> 0.30131004 | D9: =IF('Income Statement'!D9=0,0,D7/'Income Statement'!D9) -> 0.3752505 | E9: =IF('Income Statement'!E9=0,0,E7/'Income Statement'!E9) -> 0.33050797 | F9: =IF('Income Statement'!F9=0,0,F7/'Income Statement'!F9) -> 0.089620431 | G9: =IF('Income Statement'!G9=0,0,G7/'Income Statement'!G9) -> 0.56626773 | H9: =IF('Income Statement'!H9=0,0,H7/'Income Statement'!H9) -> 0.57341322
B10: Bharti Airtel consolidated capex (Rs cr) | H10: 28300 | J10: FY26 only: c.US$3.23bn reported for Bharti Airtel (NSE: BHARTIARTL), converted at Rs 87.6/US$. Earlier years removed - the prior figures were not sourced.
B11: Vi capex as % of Airtel capex | C11: ="n/a" -> n/a | D11: ="n/a" -> n/a | E11: ="n/a" -> n/a | F11: ="n/a" -> n/a | G11: ="n/a" -> n/a | H11: =IF(H10=0,0,H7/H10) -> 0.38212014 | J11: FY26: Vi spent roughly 38% of Airtel consolidated capex while carrying about half its subscriber base.
B12: Capital work-in-progress (₹ cr) | C12: 606 | D12: 364 | E12: 17876 | F12: 18189 | G12: 18213 | H12: 15274 | J12: Frozen near Rs 18,200 cr FY23-FY25 - equipment procured but uncommissioned for want of funding - then drawn down in FY26.
B14: CONSEQUENCE — SUBSCRIBER & SHARE EROSION
B15: Subscribers (million) | C15: ='Income Statement'!C30 -> 267.8 | D15: ='Income Statement'!D30 -> 243.8 | E15: ='Income Statement'!E30 -> 225.9 | F15: ='Income Statement'!F30 -> 212.6 | G15: ='Income Statement'!G30 -> 198.2 | H15: ='Income Statement'!H30 -> 192.8
B16: Net adds (million) | D16: =D15-C15 -> -24 | E16: =E15-D15 -> -17.9 | F16: =F15-E15 -> -13.3 | G16: =G15-F15 -> -14.4 | H16: =H15-G15 -> -5.4
B17: Cumulative subscribers lost vs FY21 | C17: =C15-$C$15 -> 0 | D17: =D15-$C$15 -> -24 | E17: =E15-$C$15 -> -41.9 | F17: =F15-$C$15 -> -55.2 | G17: =G15-$C$15 -> -69.6 | H17: =H15-$C$15 -> -75 | J17: c.75 million subscribers lost across six years
B18: Revenue market share (%, approx) | J18: Row cleared: the prior figures were unsourced. Populate from TRAI Performance Indicator Reports (quarterly AGR / revenue market share tables).
B20: MECHANISM
B21: • CAPITAL BUDGETING SUSPENDED. Management guidance stated FY26 capex beyond a committed ₹5,000-6,000 cr was 'contingent on successful closure of a debt fundraise'. Projects were selected on whether cash existed in the month they fell due, not on return. The binding constraint moved from the hurdle rate to the cash balance.
B22: • PREDICTABLE PATHOLOGIES. Maintenance capex (no visible NPV, prevents degradation) deferred first. High-NPV expansion postponed because payback lies beyond the liquidity horizon. Sunk capital stranded as CWIP because the final tranche was unavailable. All three visible in the accounts.
B23: • THE 5G DECISION. Vi bought 5G spectrum in the 2022 auction — incurring the liability — then could not deploy. Jio and Airtel launched nationally through 2022-23; Vi began a selective rollout only in 2025. Three years of carrying cost on an unmonetisable asset while rivals took its highest-ARPU customers. Not recoverable.
B24: • DIVESTMENT AS LIQUIDITY. Progressive monetisation of the Indus Towers stake; fibre and data-centre assets repeatedly floated for sale. Each deal bought a quarter of liquidity and permanently reduced strategic optionality. Selling infrastructure to pay for infrastructure is value-destructive; Vi did it because the alternative was default.
B25: - DEBT OVERHANG (Myers 1977). With net worth at -Rs 1,04,167 cr in FY24, the entire value of any network upgrade would accrue to the Government and lenders; existing shareholders would capture nothing. Vodafone Group wrote its Indian investment to nil and declined further equity; the Birlas contributed only modestly. The underinvestment was the RATIONAL shareholder response to an overhang - which is why the fix had to come from the creditor side.
B26: - THE INFLECTION. Once the overhang eased: a Rs 45,000 cr three-year capex programme, a US$3.6bn vendor equipment arrangement, and in Q1 FY27 the FIRST NET SUBSCRIBER ADDITION SINCE THE 2018 MERGER (193.1mn, up from 192.8mn) with customer ARPU +10.2% YoY to Rs 195.
B28: INVESTMENT CASH FLOW & ASSET BASE
B29: Cash flow from investing activities (Rs cr) | C29: 1075 | D29: -5730 | E29: -5414 | F29: -1907 | G29: -16248 | H29: -6104 | J29: Audited consolidated cash flow statements (C-MOTS via Screener). FY21 is the only positive year - proceeds from monetisation of the Indus Towers stake exceeded capital spending.
B30: Capex (cash purchase of fixed assets) | C30: ='Income Statement'!C25 -> 5106 | D30: ='Income Statement'!D25 -> 5992 | E30: ='Income Statement'!E25 -> 5537 | F30: ='Income Statement'!F25 -> 1530 | G30: ='Income Statement'!G25 -> 10220 | H30: ='Income Statement'!H25 -> 10814 | J30: Same figure as row 7. Repeated here so the investing cash flow can be read against it.
B31: Net fixed assets, closing (PP&E + intangibles) | C31: 167490 | D31: 156819 | E31: 156255 | F31: 140125 | G31: 141320 | H31: 143086 | J31: Consolidated balance sheet, C-MOTS via Screener. Net of accumulated depreciation and amortisation.
B32: YoY movement in net fixed assets | C32: =IF(COLUMN()=3,"n/a",C31-OFFSET(C31,0,-1)) -> n/a | D32: =IF(COLUMN()=3,"n/a",D31-OFFSET(D31,0,-1)) -> -10671 | E32: =IF(COLUMN()=3,"n/a",E31-OFFSET(E31,0,-1)) -> -564 | F32: =IF(COLUMN()=3,"n/a",F31-OFFSET(F31,0,-1)) -> -16130 | G32: =IF(COLUMN()=3,"n/a",G31-OFFSET(G31,0,-1)) -> 1195 | H32: =IF(COLUMN()=3,"n/a",H31-OFFSET(H31,0,-1)) -> 1766 | J32: Negative in FY22-FY24: depreciation exceeded additions, so the asset base was shrinking. Turns positive from FY25.
B33: of which: net property, plant & equipment | D33: 53957 | E33: 60121 | F33: 52815 | G33: 58668 | H33: 65694 | J33: S&P Global Market Intelligence via stockanalysis.com. FY21 split not available in the sources used.
B34: of which: other intangible assets (incl. spectrum) | D34: 103226 | E34: 114010 | F34: 105499 | G34: 100865 | H34: 92666 | J34: Falls every year from FY23: spectrum is amortised but little new spectrum was added after the 2022 auction.
B35: Gross additions per the PP&E schedule | C35: n/a | D35: n/a | E35: n/a | F35: n/a | G35: n/a | H35: n/a | J35: NOT AVAILABLE in the sources used. Disclosed only in the fixed-asset note of the statutory annual report. The capex row above (cash purchases) is the closest sourced proxy.
B37: CAPITAL WORK-IN-PROGRESS MOVEMENT (Rs cr)
B38: Opening CWIP | C38: 1138 | D38: =OFFSET(D40,0,-1) -> 606 | E38: =OFFSET(E40,0,-1) -> 364 | F38: =OFFSET(F40,0,-1) -> 17876 | G38: =OFFSET(G40,0,-1) -> 18189 | H38: =OFFSET(H40,0,-1) -> 18213 | J38: FY21 opening is the 31-Mar-2020 closing balance of Rs 1,138 cr (Screener). Later years roll forward from the prior closing.
B39: Net movement during the year | C39: =C40-C38 -> -532 | D39: =D40-D38 -> -242 | E39: =E40-E38 -> 17512 | F39: =F40-F38 -> 313 | G39: =G40-G38 -> 24 | H39: =H40-H38 -> -2939 | J39: The FY23 jump of +Rs 17,512 cr is equipment procured but not commissioned. FY24 +313 and FY25 +24 are effectively frozen. FY26 -2,939 is the first real drawdown as equipment was finally put into service.
B40: Closing CWIP | C40: =C12 -> 606 | D40: =D12 -> 364 | E40: =E12 -> 17876 | F40: =F12 -> 18189 | G40: =G12 -> 18213 | H40: =H12 -> 15274
B41: Additions to CWIP during the year | C41: n/a | D41: n/a | E41: n/a | F41: n/a | G41: n/a | H41: n/a | J41: NOT AVAILABLE in the sources used. Gross CWIP additions and capitalisations appear only in the CWIP ageing note of the statutory annual report. Only opening, closing and the net movement can be sourced here.
B42: Capitalised / transferred to fixed assets | C42: n/a | D42: n/a | E42: n/a | F42: n/a | G42: n/a | H42: n/a | J42: Same limitation. Do not infer additions from the net movement - it nets capitalisations and write-offs.
B44: WORKING CAPITAL -> INVESTMENT LINKAGE
B45: Net working capital (Rs cr) | C45: ='Working Capital'!C21 -> -52303 | D45: ='Working Capital'!D21 -> -44299 | E45: ='Working Capital'!E21 -> -46122 | F45: ='Working Capital'!F21 -> -41232 | G45: ='Working Capital'!G21 -> -24575 | H45: ='Working Capital'!H21 -> -17813
B46: Liquid assets: cash + short-term investments | C46: ='Working Capital'!C29 -> n/a | D46: ='Working Capital'!D29 -> 1459 | E46: ='Working Capital'!E29 -> 235 | F46: ='Working Capital'!F29 -> 169 | G46: ='Working Capital'!G29 -> 6310 | H46: ='Working Capital'!H29 -> 3715
B47: Capex as % of revenue | C47: =C8 -> 0.12171053 | D47: =D8 -> 0.15557171 | E47: =E8 -> 0.13128008 | F47: =F8 -> 0.035871706 | G47: =G8 -> 0.2345543 | H47: =H8 -> 0.24099124
...

Sheet Investment Timeline
B2: INVESTMENT & 5G ROLLOUT TIMELINE
B3: Vodafone Idea Ltd (NSE: IDEA / BSE: 532822). Every row carries a source. Amounts in Rs crore unless stated. Nothing on this sheet is estimated.
B5: Date | C5: FY | D5: Event | E5: Amount (Rs cr) | F5: Category | G5: What it evidences | H5: Source | I5: URL
D6: DISTRESS PHASE - FY21 to FY24
B7: Dec 2020 - Mar 2021 | C7: FY21 | D7: Monetisation of the Indus Towers shareholding; gains supported the Q3 FY21 result | E7: see note | F7: Divestment | G7: Asset sale, not operations, funded the year. FY21 is the only year with positive investing cash flow (+1,075 cr). | H7: Business Standard, 14-Feb-2021 | I7: https://www.business-standard.com/amp/article/companies/vodafone-idea-third-quarter-net-loss-narrows-to-rs-4532-crore-121021301519_1.html
B8: Mar 2021 | C8: FY21 | D8: Spectrum auction - Vi acquired spectrum for Rs 1,993.40 cr | E8: 1993 | F8: Spectrum | G8: Smallest of the three operators by a wide margin: Jio Rs 57,123 cr, Airtel Rs 18,699 cr. | H8: Business Standard, 01-Aug-2022 | I8: https://www.business-standard.com/article/companies/jio-bought-24-740-mhz-of-5g-spectrum-airtel-19-867-mhz-vaishnaw-122080101156_1.html
B9: Aug 2022 | C9: FY23 | D9: First 5G auction - Vi acquired 3300 MHz in 17 circles and 26 GHz in 16 circles | E9: 18799 | F9: Spectrum | G9: Liability incurred but not deployable. Jio and Airtel launched 5G within months; Vi took 31 months. | H9: Business Standard, 01-Aug-2022 | I9: https://www.business-standard.com/article/companies/jio-bought-24-740-mhz-of-5g-spectrum-airtel-19-867-mhz-vaishnaw-122080101156_1.html
B10: FY23 | C10: FY23 | D10: CWIP rises from Rs 364 cr to Rs 17,876 cr | E10: 17512 | F10: Deferral | G10: Equipment procured but not commissioned. The single clearest balance-sheet marker of deferred investment. | H10: Screener consolidated balance sheet | I10: https://www.screener.in/company/IDEA/consolidated/
B11: Aug 2023 | C11: FY24 | D11: Vi sought the 30-day grace period on a Rs 1,680 cr spectrum instalment due 17-Aug-2023 | E11: 1680 | F11: Deferral | G11: Direct evidence that liquidity, not policy, set the investment pace. Paid with interest under the NIA grace terms. | H11: Business Standard / PTI, 16-Aug-2023 | I11: https://www.business-standard.com/amp/companies/news/voda-idea-to-pay-rs-1-680-cr-auction-instalment-with-delay-of-30-days-123081600754_1.html
B12: FY24 | C12: FY24 | D12: Capex falls to Rs 1,530 cr, 3.6% of revenue; CWIP essentially unchanged at Rs 18,189 cr | E12: 1530 | F12: Deferral | G12: The low point. Sustaining capex in mobile is normally 15-20% of revenue. | H12: Screener cash flow and balance sheet | I12: https://www.screener.in/company/IDEA/consolidated/
B13: 2024 | C13: FY24/25 | D13: Overdue payments to tower and equipment vendors of about Rs 13,500 cr | E13: 13500 | F13: Deferral | G13: Vendors were financing the company involuntarily - the commercial half of the working capital deficit. | H13: SDxCentral, 23-Sep-2024 | I13: https://www.sdxcentral.com/news/vodafone-idea-signs-36bn-network-equipment-deal-with-nokia-ericsson-and-samsung-in-india/
D14: RECOVERY PHASE - FY25 to Q1 FY27
B15: Apr-May 2024 | C15: FY25 | D15: FPO and preferential issues raised about Rs 24,000 cr of equity | E15: 24000 | F15: Financing | G15: The liquidity event that unblocked capex. Vi stated capex was being funded from this raise. | H15: Mobile World Live, Sep-2024 | I15: https://www.mobileworldlive.com/operators/vodafone-idea-strikes-3-6b-deal-with-vendor-giants/
B16: Jun 2024 | C16: FY25 | D16: June 2024 auction - Vi acquired 30 MHz for Rs 3,510.40 cr | E16: 3510 | F16: Spectrum | G16: Renewal of expiring 900/1800 MHz holdings rather than expansion. | H16: Outlook Business; DoT/PIB auction release | I16: https://www.outlookbusiness.com/corporate/vodafone-idea-gets-2683-cr-dot-notice-for-alleged-spectrum-rollout-lapse
B17: Jun 2024 | C17: FY25 | D17: Equity issued to Nokia and Ericsson to settle overdue dues (1.5% and 0.9% stakes) | E17: 2460 | F17: Deferral | G17: Arrears settled in shares rather than cash - a distress mechanism, and dilution caused by deferred investment. | H17: Mobile World Live, Sep-2024 | I17: https://www.mobileworldlive.com/operators/vodafone-idea-strikes-3-6b-deal-with-vendor-giants/
B18: 22 Sep 2024 | C18: FY25 | D18: Three-year network equipment contracts with Nokia, Ericsson and Samsung, US$3.6bn | E18: 30000 | F18: Capex programme | G18: First step of a three-year US$6.6bn (Rs 55,000 cr) plan: 4G coverage from 1.03bn to 1.2bn people, plus 5G launch. | H18: Business Standard, 23-Sep-2024 | I18: https://www.business-standard.com/amp/markets/news/vodafone-idea-soars-8-on-rs-30k-cr-deal-with-nokia-ericsson-samsung-124092300170_1.html
B19: Dec 2024 | C19: FY25 | D19: 5G trials begin across 17 selected locations | F19: 5G rollout | G19: Trials started only 28 months after the spectrum was bought. | H19: Outlook Business, Feb-2025 | I19: https://www.outlookbusiness.com/corporate/vodafone-idea-starts-5g-trial-in-mumbai-heres-the-timeline-for-pan-india-launch
B20: FY25 | C20: FY25 | D20: Capex rises to Rs 10,220 cr; investing cash outflow Rs 16,248 cr, the largest of the period | E20: 10220 | F20: Recovery | G20: Capex up 6.7x on FY24, immediately after the equity raise. The linkage to liquidity is direct. | H20: Screener cash flow statement | I20: https://www.screener.in/company/IDEA/consolidated/
B21: Mar 2025 | C21: FY25 | D21: Commercial 5G launch in Mumbai - Vi becomes the third Indian operator to offer 5G | F21: 5G rollout | G21: 31 months after acquiring the spectrum in Aug-2022. | H21: Outlook Business; company Q3 FY25 disclosure | I21: https://www.outlookbusiness.com/corporate/vodafone-idea-starts-5g-trial-in-mumbai-heres-the-timeline-for-pan-india-launch
B22: Apr-May 2025 | C22: FY26 | D22: 5G live in Chandigarh and Patna; Delhi-NCR on 15-May-2025 | F22: 5G rollout | G22: Phased rollout targeted at the 17 priority circles where 5G spectrum was held. | H22: RCR Wireless, 19-May-2025 | I22: https://rcrwireless.com/20250519/5g/vodafone-idea-5
B23: 11 Jun 2025 | C23: FY26 | D23: 5G launched in Bengaluru | F23: 5G rollout | G23: Fifth city. Target was all 17 priority circles by August 2025. | H23: Business Standard, 11-Jun-2025 | I23: https://www.business-standard.com/amp/markets/news/vodafone-idea-share-price-rises-after-company-launches-5g-in-bengaluru-125061100236_1.html
B24: FY26 | C24: FY26 | D24: 5G launched across 83 cities; 4G coverage extended by 48mn people to above 86% of population | F24: 5G rollout | G24: More than 17,300 broadband towers added, taking the total to 202,008. | H24: Zee Business / company FY26 results, 16-May-2026 | I24: https://www.zeebiz.com/companies/news-vodafone-idea-q4-results-vi-posts-rs-51970-crore-profit-on-one-time-agr-gain-arpu-rises-to-rs-190-395649
B25: FY26 | C25: FY26 | D25: Company-disclosed capex of Rs 8,742 cr (Rs 10,814 cr on the cash flow statement basis used here) | E25: 8742 | F25: Recovery | G25: Second consecutive year of sustained investment, funded alongside the AGR reassessment and equity conversion. | H25: Kotak Neo / company FY26 results | I25: https://www.kotakneo.com/news/market-news/vodafone-idea-q4fy26-profit-agr-gain-results/
B26: 16 May 2026 | C26: FY26 | D26: Three-year capex programme of Rs 45,000 cr announced, stepping up from Q1 FY27 | E26: 45000 | F26: Capex programme | G26: Alongside targets of sustained net customer additions, double-digit revenue growth and tripling EBITDA. | H26: Quartr / Q4 FY26 earnings call | I26: https://quartr.com/events/vodafone-idea-limited-idea-q4-25-26_FsFsOFAe
B27: Q1 FY27 | C27: FY27 | D27: Capex of Rs 1,930 cr; orders worth Rs 9,000 cr placed to date; 5G live in over 200 cities | E27: 1930 | F27: Recovery | G27: Deployment described as muted on supply-chain constraints. First net subscriber addition since the 2018 merger. | H27: TelecomLead / company Q1 FY27 presentation, 15-Sep-2026 | I27: https://telecomlead.com/4g-lte/vodafone-idea-q1-fy27-revenue-hits-rs-11689-cr-arpu-rs-195-as-5g-expands-to-200-cities-127199
D29: NOT SOURCED - DO NOT FILL IN WITHOUT A CITATION
D30: Gross additions and capitalisations within CWIP by year - available only in the CWIP ageing note of the statutory annual report.
D31: Gross additions per the property, plant and equipment schedule - fixed-asset note of the statutory annual report.
D32: Year-by-year Bharti Airtel capex before FY26 - Bharti Airtel (NSE: BHARTIARTL) annual reports.
D33: Revenue market share by year - TRAI Performance Indicator Reports.

Sheet Financing
B2: Impact on Financing Decisions
B3: Distress removed the ability to CHOOSE a capital structure. Financing became an outcome, not a decision.
B5: ₹ crore (consolidated) | C5: FY21 | D5: FY22 | E5: FY23 | F5: FY24 | G5: FY25 | H5: FY26
B6: CAPITAL STRUCTURE
B7: Equity share capital (₹ cr, FV ₹10) | C7: 28735 | D7: 32119 | E7: 48680 | F7: 50120 | G7: 71393 | H7: 108343 | J7: 3.8x expansion, almost all issued at or near ₹10 face value
B8: Shares outstanding (crore) | C8: =C7/10 -> 2873.5 | D8: =D7/10 -> 3211.9 | E8: =E7/10 -> 4868 | F8: =F7/10 -> 5012 | G8: =G7/10 -> 7139.3 | H8: =H7/10 -> 10834.3
B9: Dilution vs FY21 (x) | C9: =IF($C$7=0,0,C7/$C$7) -> 1 | D9: =IF($C$7=0,0,D7/$C$7) -> 1.1177658 | E9: =IF($C$7=0,0,E7/$C$7) -> 1.6941013 | F9: =IF($C$7=0,0,F7/$C$7) -> 1.7442144 | G9: =IF($C$7=0,0,G7/$C$7) -> 2.4845311 | H9: =IF($C$7=0,0,H7/$C$7) -> 3.7704193
B10: Net worth (₹ cr) | C10: ='Income Statement'!C21 -> -38228 | D10: ='Income Statement'!D21 -> -61965 | E10: ='Income Statement'!E21 -> -74359 | F10: ='Income Statement'!F21 -> -104167 | G10: ='Income Statement'!G21 -> -70320 | H10: ='Income Statement'!H21 -> -35758
B11: Funded bank debt (₹ cr) | G11: 2326 | H11: 726 | J11: Debt from banks and financial institutions per quarterly results. FY24 cleared - not separately disclosed at 31-Mar-2024. Rs 211 cr at 30-Jun-2026. Lenders did not merely decline new exposure, they exited.
B12: AGR dues per DoT reassessment (Rs cr) | H12: 64046 | J12: Finalised by the DoT committee for FY07-FY19 and communicated to the company on 30-Apr-2026, down from Rs 87,695 cr. Total government payment obligations including deferred spectrum are in the FY26 annual report.
B14: SHAREHOLDING — CREDITOR BECAME OWNER (%)
B15: Government of India | C15: 0 | D15: 0 | E15: 0.3318 | F15: 0.3223 | G15: 0.2263 | H15: 0.4902 | J15: At 31 March each year. The prior version put the 48.99% conversion in FY25 - the shares were allotted in Q1 FY26, so GoI was 22.63% at 31-Mar-2025 and 49.02% at 31-Mar-2026.
B16: Promoter group (Vodafone Group + Aditya Birla Group) | C16: 0.7205 | D16: 0.7499 | E16: 0.5036 | F16: 0.4891 | G16: 0.388 | H16: 0.2564 | J16: Combined promoter holding. The Vodafone / Birla split by year is not in the source used; Vodafone Group reported 24.4% at 31-Mar-2025.
B17: Institutional (FII + DII) | C17: 0.0567 | D17: 0.0528 | E17: 0.0282 | F17: 0.0417 | G17: 0.15 | H17: 0.1175
B18: Public & others | C18: =1-C15-C16-C17 -> 0.2228 | D18: =1-D15-D16-D17 -> 0.1973 | E18: =1-E15-E16-E17 -> 0.1364 | F18: =1-F15-F16-F17 -> 0.1469 | G18: =1-G15-G16-G17 -> 0.2357 | H18: =1-H15-H16-H17 -> 0.1359
B19: Check — total | C19: =SUM(C15:C18) -> 1 | D19: =SUM(D15:D18) -> 1 | E19: =SUM(E15:E18) -> 1 | F19: =SUM(F15:F18) -> 1 | G19: =SUM(G15:G18) -> 1 | H19: =SUM(H15:H18) -> 1
B21: MANDATORY OUTFLOWS vs CAPACITY (₹ cr)
B22: Forward spectrum obligations
C23: FY27 | D23: FY28 | E23: FY29 | F23: FY26 CFO
B24: Spectrum payable | F24: ='Income Statement'!H24 -> 19411
B25: Forward spectrum instalments cleared: the prior figures were unsourced. Populate from the contractual maturities note of the FY26 annual report, then compare against FY26 CFO of Rs 19,411 cr.
B27: MECHANISM
B28: • THE PECKING ORDER RAN BACKWARDS. Myers & Majluf predict internal funds, then debt, then equity last. Vi inverted it completely. Internal accruals: unavailable (CFO of ₹8-9k cr against statutory obligations near ₹18k cr and finance cost above ₹20k cr). Debt: refused — bank exposure CUT from ₹7,620 cr to ₹726 cr, covenants breached as early as FY21, waivers sought, extra security demanded, SBI's own share price dragged by its ₹11,000 cr exposure. Equity: the only door left.
B29: • DILUTION SEQUENCE. Feb-2023: ₹16,133 cr of interest converted to equity (GoI to 33.1%). Apr-2024: ₹18,000 cr FPO at ₹11/share — the largest FPO in Indian history — plus ₹2,075 cr preferential to ABG. Mar/Apr-2025: ₹36,950 cr spectrum dues converted at ₹10/share (GoI to 48.99%). Share capital from ₹28,735 cr to ₹1,08,343 cr.
B30: - GOVERNANCE WITHOUT AN ANALOGUE. The Government of India is simultaneously the largest shareholder (49.02% at 31-Mar-2026), a very large creditor, the regulator, and the licence-fee beneficiary. The Supreme Court itself noted that the Government's shareholding gave it a direct stake in the company's survival.
B31: • THE 49% CEILING IS DELIBERATE. Crossing 50% would classify Vi as a PSU — triggering an open offer under SEBI's takeover code, sovereign responsibility for losses, and public-procurement obligations. The Government has signalled it will not go further. This CLOSES the mechanism that twice rescued the company.
B32: • TERMS REVEAL WHO HOLDS POWER. The Sep-2026 SBI-led package (SBI, Union Bank, NaBFID; c.US$3.5bn, near ten-year tenure) requires that Kumar Mangalam Birla REMAIN CHAIRMAN for the life of the loan and that promoter entities furnish repayment guarantees on default. A solvent borrower concedes neither. Lenders are contracting around the promoter's reputation and personal balance sheet because they do not trust the company's. Control rights migrated to creditors while legal ownership did not change.
B33: • COORDINATION FAILURE. SBI's approval was made conditional on private-sector banks committing first, which has held up disbursement — the classic distressed-syndication problem where no lender will move first and the state-owned bank will not carry the risk alone.
B34: • SUBSTITUTES USED WHILE CREDIT WAS CLOSED. (a) Vendor financing — the c.₹30,000 cr equipment arrangement is supplier credit replacing bank credit, at a cost buried in equipment pricing. (b) Non-bank sources in small tranches purely to maintain capex continuity. (c) Government forbearance — the 2021 four-year moratorium was economically a large sovereign loan with no covenants and no security, and the only reason Vi stayed solvent through FY22-FY25.

Sheet Findings
B2: Findings, Timeline & Conclusions
B3: Vodafone Idea Ltd — FY2021 to FY2026
B5: TIMELINE OF DISTRESS
B6: Oct 2019 | C6: Supreme Court upholds DoT's AGR definition. Vi provisions c.₹44,000 cr. A regulatory dispute becomes a balance-sheet event.
B7: Sep 2021 | C7: Telecom reform package: four-year moratorium on AGR and spectrum dues, plus an option to convert accrued interest into equity. Defers the problem rather than solving it.
B8: Feb 2023 | C8: ₹16,133 cr of interest converted to equity. Government becomes largest shareholder at 33.1%. Banks still refuse fresh credit.
B9: Apr 2024 | C9: ₹18,000 cr FPO at ₹11/share — largest in Indian history — plus ₹2,075 cr preferential allotment to the Aditya Birla Group.
B10: Mar-Apr 2025 | C10: Rs 36,950 cr of spectrum dues agreed for conversion at Rs 10/share. Shares allotted in Q1 FY26, taking the Government to 49.02% and capping it below 50% to avoid PSU classification.
B11: Oct-Nov 2025 | C11: Supreme Court permits the Centre to reconsider Vi's AGR dues, then widens the order to comprehensive reassessment up to FY17. Recovery of ₹87,695 cr frozen.
B12: Jan-Apr 2026 | C12: DoT committee (incl. a CAG representative) reassesses. AGR dues cut ₹23,649 cr (c.27%) to ₹64,046 cr, repayment stretched to FY41.
B13: May 2026 | C13: FY26 results: Rs 34,552 cr net profit on a Rs 57,491 cr exceptional AGR write-back. Pre-exceptional loss still Rs 22,939 cr.
B14: Aug-Sep 2026 | C14: SBI in-principle approval for its share of a ₹45,000 cr capex facility; SBI-led consortium lines up c.US$3.5bn over c.10 years, conditional on Birla remaining chairman and promoter guarantees.
B15: THE DISTRESS LOOP
B16: Operating loop | C16: Working capital deficit -> capex starvation (Rs 1,530 cr in FY24) -> network falls behind (no 5G, weak 4G) -> subscriber and ARPU loss (268mn -> 193mn) -> weaker cash flow -> deeper working capital deficit.
B17: Financing loop | C17: Working capital deficit destroys creditworthiness → debt foreclosed → forced dilutive equity → promoters diluted to the point they will not fund the next round → absence of promoter support itself cited by lenders as reason to refuse credit. Vi went round this loop twice.
B18: Where it broke | C18: NOT at the operating node. Tariff hikes raised Q4 exit ARPU 78% between FY21 and FY26 and still could not break the cycle, because the constraint was never revenue. It broke at the LIABILITY node: Rs 53,000 cr converted to equity plus Rs 23,649 cr written off.
B19: RESOLVED IN FY26
B20: AGR liability | C20: Cut ₹23,649 cr to ₹64,046 cr. Repayment stretched: token amounts to FY31, minimum ₹100 cr annually to FY35, then six instalments of ₹10,608 cr between Mar-2036 and Mar-2041.
B21: Net worth | C21: Improved from -Rs 70,320 cr to -Rs 35,758 cr.
B22: Cash generation | C22: Operating cash flow more than doubled to ₹19,411 cr (+109%).
B23: Bank position | C23: Funded bank debt down to ₹726 cr; ₹6,400 cr of new long-term facilities secured in Q1 FY27.
B24: Commercial | C24: First net subscriber addition since the 2018 merger. ARPU ₹195, up 10.2% YoY.
B25: STILL UNRESOLVED
B26: Still insolvent | C26: Net worth remains negative at -Rs 35,758 cr - technically insolvent on a book basis.
B27: The FY29 cliff | C27: Large deferred spectrum instalments fall due from FY27 onwards against operating cash flow near Rs 19,000 cr. Quantify from the FY26 annual report before citing - see the Financing tab.
B28: Facility undisbursed | C28: The US$3.5bn package awaits final lender approvals, documentation, promoter guarantees and private-bank participation.
B29: Conversion route closed | C29: The equity-conversion mechanism is capped at the 49% ceiling.
B30: Competitive gap | C30: Under 20% revenue market share against two rivals investing at multiples of Vi's rate. ₹45,000 cr over three years remains below what Jio and Airtel each spend annually.
B31: Liquidity slipped | C31: Current ratio improved from 0.24x in FY24 to 0.56x in FY25 and held at 0.55x in FY26, still far below 1.0x.
B32: CONCLUSIONS
B33: 1. Decompose, don't read | C33: A negative working-capital figure carries no information alone. Vi and Bharti Airtel both report negative working capital; one is a competitive advantage from prepaid collections, the other is deferred insolvency. Vi's decomposition shows receivables and inventory performing well while statutory maturities and involuntarily stretched payables drive the entire deficit.
B34: 2. It does not stay put | C34: Working-capital distress converts capital budgeting from an NPV exercise into a cash-availability exercise, and the resulting underinvestment compounds. Three years of deferred 5G cost a subscriber base that cannot simply be bought back.
B35: 3. Choice dies before access | C35: Vi did not choose a capital structure between FY21 and FY26; it accepted whatever remained, in reverse pecking order, at terms — promoter guarantees, chairman-continuity covenants — no solvent borrower would sign.
B36: 4. Models assume arm's-length creditors | C36: Altman's Z-score classified Vi as failed for six consecutive years. It survived because its principal creditor had reasons beyond recovery to keep it alive: maintaining three-player competition, protecting public-sector bank exposure, and defending its own 49% stake.
B37: 5. THE CENTRAL FINDING | C37: Operating improvement is NOT a sufficient remedy for balance-sheet distress. Vi raised ARPU 68%, expanded margins four points and doubled operating cash flow — and none of it altered the trajectory until ₹53,000 cr of liabilities were converted and ₹23,649 cr written off. Liability restructuring and operating turnaround are COMPLEMENTS, not substitutes. Attempting the second without the first simply funds the creditors.

Sheet Sheet1

Sheet Sources
B2: SOURCE REGISTER
B3: Vodafone Idea Ltd | Ticker: NSE: IDEA | BSE: 532822 | ISIN INE669E01016 | Bloomberg IDEA:IN | Reuters VODA.NS | Yahoo IDEA.NS
B4: Peer referenced: Bharti Airtel Ltd (NSE: BHARTIARTL / BSE: 532454). All figures consolidated, Rs crore, unless stated.
B6: # | C6: Line item / tab | D6: FY covered | E6: Value used | F6: Source | G6: Basis & notes | H6: URL
C7: INCOME STATEMENT
B8: 1 | C8: Revenue from operations | D8: FY21-FY26 | E8: 41,952 / 38,516 / 42,177 / 42,652 / 43,572 / 44,873 | F8: Screener (C-MOTS), consolidated P&L | G8: Unchanged - already matched the filings. | H8: https://www.screener.in/company/IDEA/consolidated/
B9: 2 | C9: EBITDA | D9: FY21-FY26 | E9: 16,946 / 15,968 / 16,753 / 17,072 / 18,048 / 18,859 | F9: Screener (C-MOTS), operating profit | G9: CORRECTED. One consistent basis across all six years. Company-reported EBITDA is Rs 18,127 cr (FY25) and Rs 19,003 cr (FY26). | H9: https://www.screener.in/company/IDEA/consolidated/
B10: 3 | C10: Depreciation & amortisation | D10: FY21-FY26 | E10: 23,638 / 23,584 / 23,050 / 22,634 / 21,973 / 22,108 | F10: Screener (C-MOTS) | G10: CORRECTED FY24 and FY26. Includes Ind AS 116 lease depreciation. | H10: https://www.screener.in/company/IDEA/consolidated/
B11: 4 | C11: Finance cost | D11: FY21-FY26 | E11: 17,998 / 20,981 / 23,354 / 25,766 / 24,543 / 21,495 | F11: Screener (C-MOTS) | G11: CORRECTED. The prior row was mis-aligned by one year from FY22 onward. | H11: https://www.screener.in/company/IDEA/consolidated/
B12: 5 | C12: Net profit / (loss) | D12: FY21-FY26 | E12: -44,233 / -28,245 / -29,301 / -31,238 / -27,384 / 34,552 | F12: Screener (C-MOTS); company results release 16-May-2026 | G12: Unchanged. FY26 split re-derived: pre-exceptional -22,939 plus exceptional +57,491. | H12: https://www.zeebiz.com/companies/news-vodafone-idea-q4-results-vi-posts-rs-51970-crore-profit-on-one-time-agr-gain-arpu-rises-to-rs-190-395649
B13: 6 | C13: FY26 exceptional gain | D13: FY26 | E13: 57,491 | F13: Company Q4 FY26 results release, 16-May-2026 | G13: Gain on DoT reassessment of AGR dues, recognised in Q4 FY26. | H13: https://www.zeebiz.com/companies/news-vodafone-idea-q4-results-vi-posts-rs-51970-crore-profit-on-one-time-agr-gain-arpu-rises-to-rs-190-395649
B14: 7 | C14: Net worth | D14: FY21-FY26 | E14: -38,228 / -61,965 / -74,359 / -1,04,167 / -70,320 / -35,758 | F14: Screener (C-MOTS): equity capital + reserves | G14: CORRECTED FY26 (was -35,363). | H14: https://www.screener.in/company/IDEA/consolidated/
B15: 8 | C15: Cash flow from operations | D15: FY21-FY26 | E15: 15,640 / 17,387 / 18,869 / 20,826 / 9,290 / 19,411 | F15: Screener (C-MOTS), audited cash flow statements; FY21-FY22 cross-checked to Equitymaster | G15: CORRECTED. The prior row understated FY21-FY24 by roughly half. | H15: https://www.screener.in/company/IDEA/consolidated/
